<?xml version="1.0" ?>
<sdf version="1.4">

<model name='turtlebot'>

      <link name='rack'>
        <inertial>
          <pose>0.001453 -0.000453 0.029787 0.000000 0.000000 0.000000</pose>
          <inertia>
            <ixx>0.058640</ixx>
            <ixy>0.000124</ixy>
            <ixz>0.000615</ixz>
            <iyy>0.058786</iyy>
            <iyz>0.000014</iyz>
            <izz>1.532440</izz>
          </inertia>
          <mass>2.234000</mass>
        </inertial>

        <collision name="tag1_collision">
          <pose>0 0 0.44 0 0 0</pose>
          <geometry>
            <box>
                <size>0.4 0.2 0.01</size>
            </box>
          </geometry>
        </collision>
        <visual name="tag1_visual">
          <pose>0 0 0.44 0 0 0</pose>
          <cast_shadows>true</cast_shadows>
          <geometry>
            <box>
                <size>0.4 0.2 0.01</size>
            </box>
          </geometry>
          <material>
            <diffuse>0 1 0 1</diffuse>
          </material>
        </visual>

        <collision name="tag2_collision">
          <pose>0.14 0 0.45 0 0 0</pose>
          <geometry>
            <box>
                <size>0.12 0.2 0.01</size>
            </box>
          </geometry>
        </collision>
        <visual name="tag2_visual">
          <pose>0.14 0 0.45 0 0 0</pose>
          <cast_shadows>true</cast_shadows>
          <geometry>
            <box>
                <size>0.12 0.2 0.01</size>
            </box>
          </geometry>
          <material>
            <diffuse>0 0 1 1</diffuse>
          </material>
        </visual>

        <collision name='plate_0_collision'>
          <pose>-0.043340 0.000000 0.084757 0.000000 0.000000 0.000000</pose>
          <geometry>
            <box>
              <size>0.233502 0.314845 0.006401</size>
            </box>
          </geometry>
          <max_contacts>10</max_contacts>
          <surface>
            <bounce/>
            <friction>
              <ode/>
            </friction>
            <contact>
              <ode/>
            </contact>
          </surface>
        </collision>
        <visual name='plate_0_visual'>
          <pose>-0.043340 0.000000 0.084757 0.000000 0.000000 0.000000</pose>
          <geometry>
            <mesh>
              <uri>model://turtlebotJde2cam/meshes/plate_0_logo.dae</uri>
            </mesh>
          </geometry>
        </visual>
        <collision name='plate_1_collision'>
          <pose>-0.002660 0.000000 0.141907 0.000000 0.000000 0.000000</pose>
          <geometry>
            <box>
              <size>0.314856 0.314856 0.006401</size>
            </box>
          </geometry>
          <max_contacts>10</max_contacts>
          <surface>
            <bounce/>
            <friction>
              <ode/>
            </friction>
            <contact>
              <ode/>
            </contact>
          </surface>
        </collision>
        <visual name='plate_1_visual'>
          <pose>-0.002660 0.000000 0.141907 0.000000 0.000000 0.000000</pose>
          <geometry>
            <mesh>
              <uri>model://turtlebotJde2cam/meshes/plate_1_logo.dae</uri>
            </mesh>
          </geometry>
        </visual>
        <collision name='plate_2_collision'>
          <pose>-0.002660 0.000000 0.199108 0.000000 0.000000 0.000000</pose>
          <geometry>
            <box>
              <size>0.314856 0.314856 0.006401</size>
            </box>
          </geometry>
          <max_contacts>10</max_contacts>
          <surface>
            <bounce/>
            <friction>
              <ode/>
            </friction>
            <contact>
              <ode/>
            </contact>
          </surface>
        </collision>
        <visual name='plate_2_visual'>
          <pose>-0.002660 0.000000 0.199108 0.000000 0.000000 0.000000</pose>
          <geometry>
            <mesh>
              <uri>model://turtlebotJde2cam/meshes/plate_1_logo.dae</uri>
            </mesh>
          </geometry>
        </visual>
        <collision name='plate_3_collision'>
          <pose>-0.015820 0.000000 0.405457 0.000000 0.000000 0.000000</pose>
          <geometry>
            <box>
              <size>0.288000 0.315000 0.006401</size>
            </box>
          </geometry>
          <max_contacts>10</max_contacts>
          <surface>
            <bounce/>
            <friction>
              <ode/>
            </friction>
            <contact>
              <ode/>
            </contact>
          </surface>
        </collision>
        <visual name='plate_3_visual'>
          <pose>-0.015820 0.000000 0.405457 0.000000 0.000000 0.000000</pose>
          <geometry>
            <mesh>
              <uri>model://turtlebotJde2cam/meshes/plate_2_logo.dae</uri>
            </mesh>
          </geometry>
        </visual>
        <collision name='spacer_0_collision'>
          <pose>-0.002540 0.111468 0.079992 0.000000 0.000000 0.000000</pose>
          <geometry>
            <cylinder>
              <radius>0.012700</radius>
              <length>0.003175</length>
            </cylinder>
          </geometry>
          <max_contacts>10</max_contacts>
          <surface>
            <bounce/>
            <friction>
              <ode/>
            </friction>
            <contact>
              <ode/>
            </contact>
          </surface>
        </collision>
        <visual name='spacer_0_visual'>
          <pose>-0.002540 0.111468 0.079992 0.000000 0.000000 0.000000</pose>
          <geometry>
            <mesh>
              <uri>model://turtlebotJde2cam/meshes/68-02403-125_Spacer.dae</uri>
            </mesh>
          </geometry>
        </visual>
        <collision name='spacer_1_collision'>
          <pose>-0.002540 -0.111468 0.079992 0.000000 0.000000 0.000000</pose>
          <geometry>
            <cylinder>
              <radius>0.012700</radius>
              <length>0.003175</length>
            </cylinder>
          </geometry>
          <max_contacts>10</max_contacts>
          <surface>
            <bounce/>
            <friction>
              <ode/>
            </friction>
            <contact>
              <ode/>
            </contact>
          </surface>
        </collision>
        <visual name='spacer_1_visual'>
          <pose>-0.002540 -0.111468 0.079992 0.000000 0.000000 0.000000</pose>
          <geometry>
            <mesh>
              <uri>model://turtlebotJde2cam/meshes/68-02403-125_Spacer.dae</uri>
            </mesh>
          </geometry>
        </visual>
        <collision name='spacer_2_collision'>
          <pose>-0.072390 -0.111468 0.079992 0.000000 0.000000 0.000000</pose>
          <geometry>
            <cylinder>
              <radius>0.012700</radius>
              <length>0.003175</length>
            </cylinder>
          </geometry>
          <max_contacts>10</max_contacts>
          <surface>
            <bounce/>
            <friction>
              <ode/>
            </friction>
            <contact>
              <ode/>
            </contact>
          </surface>
        </collision>
        <visual name='spacer_2_visual'>
          <pose>-0.072390 -0.111468 0.079992 0.000000 0.000000 0.000000</pose>
          <geometry>
            <mesh>
              <uri>model://turtlebotJde2cam/meshes/68-02403-125_Spacer.dae</uri>
            </mesh>
          </geometry>
        </visual>
        <collision name='spacer_3_collision'>
          <pose>-0.072390 0.111468 0.079992 0.000000 0.000000 0.000000</pose>
          <geometry>
            <cylinder>
              <radius>0.012700</radius>
              <length>0.003175</length>
            </cylinder>
          </geometry>
          <max_contacts>10</max_contacts>
          <surface>
            <bounce/>
            <friction>
              <ode/>
            </friction>
            <contact>
              <ode/>
            </contact>
          </surface>
        </collision>
        <visual name='spacer_3_visual'>
          <pose>-0.072390 0.111468 0.079992 0.000000 0.000000 0.000000</pose>
          <geometry>
            <mesh>
              <uri>model://turtlebotJde2cam/meshes/68-02403-125_Spacer.dae</uri>
            </mesh>
          </geometry>
        </visual>
        <collision name='standoff_2in_0_collision'>
          <pose>0.067640 0.131420 0.087980 0.000000 0.000000 0.000000</pose>
          <geometry>
            <cylinder>
              <radius>0.038100</radius>
              <length>0.063500</length>
            </cylinder>
          </geometry>
          <max_contacts>10</max_contacts>
          <surface>
            <bounce/>
            <friction>
              <ode/>
            </friction>
            <contact>
              <ode/>
            </contact>
          </surface>
        </collision>
        <visual name='standoff_2in_0_visual'>
          <pose>0.067640 0.131420 0.087980 0.000000 0.000000 0.000000</pose>
          <geometry>
            <mesh>
              <uri>model://turtlebotJde2cam/meshes/68-04552-2000-RA_Turtlebot_M-F_Standoff.dae</uri>
            </mesh>
          </geometry>
        </visual>
        <collision name='standoff_2in_1_collision'>
          <pose>0.067640 -0.131420 0.087980 0.000000 0.000000 0.000000</pose>
          <geometry>
            <cylinder>
              <radius>0.038100</radius>
              <length>0.063500</length>
            </cylinder>
          </geometry>
          <max_contacts>10</max_contacts>
          <surface>
            <bounce/>
            <friction>
              <ode/>
            </friction>
            <contact>
              <ode/>
            </contact>
          </surface>
        </collision>
        <visual name='standoff_2in_1_visual'>
          <pose>0.067640 -0.131420 0.087980 0.000000 0.000000 0.000000</pose>
          <geometry>
            <mesh>
              <uri>model://turtlebotJde2cam/meshes/68-04552-2000-RA_Turtlebot_M-F_Standoff.dae</uri>
            </mesh>
          </geometry>
        </visual>
        <collision name='standoff_2in_2_collision'>
          <pose>-0.052832 -0.131420 0.087980 0.000000 0.000000 0.000000</pose>
          <geometry>
            <cylinder>
              <radius>0.038100</radius>
              <length>0.063500</length>
            </cylinder>
          </geometry>
          <max_contacts>10</max_contacts>
          <surface>
            <bounce/>
            <friction>
              <ode/>
            </friction>
            <contact>
              <ode/>
            </contact>
          </surface>
        </collision>
        <visual name='standoff_2in_2_visual'>
          <pose>-0.052832 -0.131420 0.087980 0.000000 0.000000 0.000000</pose>
          <geometry>
            <mesh>
              <uri>model://turtlebotJde2cam/meshes/68-04552-2000-RA_Turtlebot_M-F_Standoff.dae</uri>
            </mesh>
          </geometry>
        </visual>
        <collision name='standoff_2in_3_collision'>
          <pose>-0.052832 0.131420 0.087980 0.000000 0.000000 0.000000</pose>
          <geometry>
            <cylinder>
              <radius>0.038100</radius>
              <length>0.063500</length>
            </cylinder>
          </geometry>
          <max_contacts>10</max_contacts>
          <surface>
            <bounce/>
            <friction>
              <ode/>
            </friction>
            <contact>
              <ode/>
            </contact>
          </surface>
        </collision>
        <visual name='standoff_2in_3_visual'>
          <pose>-0.052832 0.131420 0.087980 0.000000 0.000000 0.000000</pose>
          <geometry>
            <mesh>
              <uri>model://turtlebotJde2cam/meshes/68-04552-2000-RA_Turtlebot_M-F_Standoff.dae</uri>
            </mesh>
          </geometry>
        </visual>
        <collision name='standoff_2in_4_collision'>
          <pose>0.067640 0.131420 0.145130 0.000000 0.000000 0.000000</pose>
          <geometry>
            <cylinder>
              <radius>0.038100</radius>
              <length>0.063500</length>
            </cylinder>
          </geometry>
          <max_contacts>10</max_contacts>
          <surface>
            <bounce/>
            <friction>
              <ode/>
            </friction>
            <contact>
              <ode/>
            </contact>
          </surface>
        </collision>
        <visual name='standoff_2in_4_visual'>
          <pose>0.067640 0.131420 0.145130 0.000000 0.000000 0.000000</pose>
          <geometry>
            <mesh>
              <uri>model://turtlebotJde2cam/meshes/68-04552-2000-RA_Turtlebot_M-F_Standoff.dae</uri>
            </mesh>
          </geometry>
        </visual>
        <collision name='standoff_2in_5_collision'>
          <pose>0.067640 -0.131420 0.145130 0.000000 0.000000 0.000000</pose>
          <geometry>
            <cylinder>
              <radius>0.038100</radius>
              <length>0.063500</length>
            </cylinder>
          </geometry>
          <max_contacts>10</max_contacts>
          <surface>
            <bounce/>
            <friction>
              <ode/>
            </friction>
            <contact>
              <ode/>
            </contact>
          </surface>
        </collision>
        <visual name='standoff_2in_5_visual'>
          <pose>0.067640 -0.131420 0.145130 0.000000 0.000000 0.000000</pose>
          <geometry>
            <mesh>
              <uri>model://turtlebotJde2cam/meshes/68-04552-2000-RA_Turtlebot_M-F_Standoff.dae</uri>
            </mesh>
          </geometry>
        </visual>
        <collision name='standoff_2in_6_collision'>
          <pose>-0.052832 -0.131420 0.145130 0.000000 0.000000 0.000000</pose>
          <geometry>
            <cylinder>
              <radius>0.038100</radius>
              <length>0.063500</length>
            </cylinder>
          </geometry>
          <max_contacts>10</max_contacts>
          <surface>
            <bounce/>
            <friction>
              <ode/>
            </friction>
            <contact>
              <ode/>
            </contact>
          </surface>
        </collision>
        <visual name='standoff_2in_6_visual'>
          <pose>-0.052832 -0.131420 0.145130 0.000000 0.000000 0.000000</pose>
          <geometry>
            <mesh>
              <uri>model://turtlebotJde2cam/meshes/68-04552-2000-RA_Turtlebot_M-F_Standoff.dae</uri>
            </mesh>
          </geometry>
        </visual>
        <collision name='standoff_2in_7_collision'>
          <pose>-0.052832 0.131420 0.145130 0.000000 0.000000 0.000000</pose>
          <geometry>
            <cylinder>
              <radius>0.038100</radius>
              <length>0.063500</length>
            </cylinder>
          </geometry>
          <max_contacts>10</max_contacts>
          <surface>
            <bounce/>
            <friction>
              <ode/>
            </friction>
            <contact>
              <ode/>
            </contact>
          </surface>
        </collision>
        <visual name='standoff_2in_7_visual'>
          <pose>-0.052832 0.131420 0.145130 0.000000 0.000000 0.000000</pose>
          <geometry>
            <mesh>
              <uri>model://turtlebotJde2cam/meshes/68-04552-2000-RA_Turtlebot_M-F_Standoff.dae</uri>
            </mesh>
          </geometry>
        </visual>
        <collision name='standoff_8in_0_collision'>
          <pose>0.067640 0.131420 0.202280 0.000000 0.000000 0.000000</pose>
          <geometry>
            <cylinder>
              <radius>0.011113</radius>
              <length>0.203200</length>
            </cylinder>
          </geometry>
          <max_contacts>10</max_contacts>
          <surface>
            <bounce/>
            <friction>
              <ode/>
            </friction>
            <contact>
              <ode/>
            </contact>
          </surface>
        </collision>
        <visual name='standoff_8in_0_visual'>
          <pose>0.067640 0.131420 0.202280 0.000000 0.000000 0.000000</pose>
          <geometry>
            <mesh>
              <uri>model://turtlebotJde2cam/meshes/68-02421-8000-RA_Turtlebot_F-F_Standoff.dae</uri>
            </mesh>
          </geometry>
        </visual>
        <collision name='standoff_8in_1_collision'>
          <pose>0.067640 -0.131420 0.202280 0.000000 0.000000 0.000000</pose>
          <geometry>
            <cylinder>
              <radius>0.011113</radius>
              <length>0.203200</length>
            </cylinder>
          </geometry>
          <max_contacts>10</max_contacts>
          <surface>
            <bounce/>
            <friction>
              <ode/>
            </friction>
            <contact>
              <ode/>
            </contact>
          </surface>
        </collision>
        <visual name='standoff_8in_1_visual'>
          <pose>0.067640 -0.131420 0.202280 0.000000 0.000000 0.000000</pose>
          <geometry>
            <mesh>
              <uri>model://turtlebotJde2cam/meshes/68-02421-8000-RA_Turtlebot_F-F_Standoff.dae</uri>
            </mesh>
          </geometry>
        </visual>
        <collision name='standoff_8in_2_collision'>
          <pose>-0.052832 -0.131420 0.202280 0.000000 0.000000 0.000000</pose>
          <geometry>
            <cylinder>
              <radius>0.011113</radius>
              <length>0.203200</length>
            </cylinder>
          </geometry>
          <max_contacts>10</max_contacts>
          <surface>
            <bounce/>
            <friction>
              <ode/>
            </friction>
            <contact>
              <ode/>
            </contact>
          </surface>
        </collision>
        <visual name='standoff_8in_2_visual'>
          <pose>-0.052832 -0.131420 0.202280 0.000000 0.000000 0.000000</pose>
          <geometry>
            <mesh>
              <uri>model://turtlebotJde2cam/meshes/68-02421-8000-RA_Turtlebot_F-F_Standoff.dae</uri>
            </mesh>
          </geometry>
        </visual>
        <collision name='standoff_8in_3_collision'>
          <pose>-0.052832 0.131420 0.202280 0.000000 0.000000 0.000000</pose>
          <geometry>
            <cylinder>
              <radius>0.011113</radius>
              <length>0.203200</length>
            </cylinder>
          </geometry>
          <max_contacts>10</max_contacts>
          <surface>
            <bounce/>
            <friction>
              <ode/>
            </friction>
            <contact>
              <ode/>
            </contact>
          </surface>
        </collision>
        <visual name='standoff_8in_3_visual'>
          <pose>-0.052832 0.131420 0.202280 0.000000 0.000000 0.000000</pose>
          <geometry>
            <mesh>
              <uri>model://turtlebotJde2cam/meshes/68-02421-8000-RA_Turtlebot_F-F_Standoff.dae</uri>
            </mesh>
          </geometry>
        </visual>
        <collision name='standoff_kinect_0_collision'>
          <pose>-0.105098 0.098000 0.202308 0.000000 0.000000 0.000000</pose>
          <geometry>
            <cylinder>
              <radius>0.001111</radius>
              <length>0.008585</length>
            </cylinder>
          </geometry>
          <max_contacts>10</max_contacts>
          <surface>
            <bounce/>
            <friction>
              <ode/>
            </friction>
            <contact>
              <ode/>
            </contact>
          </surface>
        </collision>
        <visual name='standoff_kinect_0_visual'>
          <pose>-0.105098 0.098000 0.202308 0.000000 0.000000 0.000000</pose>
          <geometry>
            <mesh>
              <uri>model://turtlebotJde2cam/meshes/68-04556-RA_Kinect_Standoff_Assy.dae</uri>
            </mesh>
          </geometry>
        </visual>
        <collision name='standoff_kinect_1_collision'>
          <pose>-0.105098 -0.098000 0.202308 0.000000 0.000000 0.000000</pose>
          <geometry>
            <cylinder>
              <radius>0.001111</radius>
              <length>0.008585</length>
            </cylinder>
          </geometry>
          <max_contacts>10</max_contacts>
          <surface>
            <bounce/>
            <friction>
              <ode/>
            </friction>
            <contact>
              <ode/>
            </contact>
          </surface>
        </collision>
        <visual name='standoff_kinect_1_visual'>
          <pose>-0.105098 -0.098000 0.202308 0.000000 0.000000 0.000000</pose>
          <geometry>
            <mesh>
              <uri>model://turtlebotJde2cam/meshes/68-04556-RA_Kinect_Standoff_Assy.dae</uri>
            </mesh>
          </geometry>
        </visual>
        <velocity_decay>
          <linear>0.000000</linear>
          <angular>0.000000</angular>
        </velocity_decay>
        <self_collide>0</self_collide>
        <kinematic>0</kinematic>
        <gravity>1</gravity>
      </link>
      <link name='laser'>
        <pose>0.155000 0.000000 0.112000 0.000000 0.000000 0.000000</pose>
        <gravity>0</gravity>
        <inertial>
          <mass>0.100000</mass>
          <inertia>
            <ixx>1.000000</ixx>
            <ixy>0.000000</ixy>
            <ixz>0.000000</ixz>
            <iyy>1.000000</iyy>
            <iyz>0.000000</iyz>
            <izz>1.000000</izz>
          </inertia>
        </inertial>
        <visual name='visual'>
          <geometry>
            <mesh>
              <uri>model://hokuyo/meshes/hokuyo.dae</uri>
            </mesh>
          </geometry>
        </visual>
        <collision name='collision-base'>
          <pose>0.000000 0.000000 -0.014500 0.000000 0.000000 0.000000</pose>
          <geometry>
            <box>
              <size>0.050000 0.050000 0.041000</size>
            </box>
          </geometry>
          <max_contacts>10</max_contacts>
          <surface>
            <bounce/>
            <friction>
              <ode/>
            </friction>
            <contact>
              <ode/>
            </contact>
          </surface>
        </collision>
        <collision name='collision-top'>
          <pose>0.000000 0.000000 0.020500 0.000000 0.000000 0.000000</pose>
          <geometry>
            <cylinder>
              <radius>0.021000</radius>
              <length>0.029000</length>
            </cylinder>
          </geometry>
          <max_contacts>10</max_contacts>
          <surface>
            <bounce/>
            <friction>
              <ode/>
            </friction>
            <contact>
              <ode/>
            </contact>
          </surface>
        </collision>
        <sensor name='laser' type='ray'>
          <ray>
            <scan>
              <horizontal>
                <samples>180</samples>
                <resolution>1.000000</resolution>
                <min_angle>-1.570000</min_angle>
                <max_angle>1.570000</max_angle>
              </horizontal>
            </scan>
            <range>
              <min>0.080000</min>
              <max>10.000000</max>
              <resolution>0.010000</resolution>
            </range>
          </ray>
          <update_rate>20.000000</update_rate>
          <plugin name='laser' filename='liblaserTurtlebotJde.so'/>
          <always_on>1</always_on>
          <visualize>1</visualize>
        </sensor>
        <velocity_decay>
          <linear>0.000000</linear>
          <angular>0.000000</angular>
        </velocity_decay>
        <self_collide>0</self_collide>
        <kinematic>0</kinematic>
      </link>
      <link name='camera_bottom_body_left'>
        <pose>-0.030000 0.076000 0.232400 -1.570000 0.000000 0.000000</pose>
        <inertial>
          <mass>0.500000</mass>
          <inertia>
            <ixx>1.000000</ixx>
            <ixy>0.000000</ixy>
            <ixz>0.000000</ixz>
            <iyy>1.000000</iyy>
            <iyz>0.000000</iyz>
            <izz>1.000000</izz>
          </inertia>
        </inertial>
        <visual name='visual'>
          <geometry>
            <mesh>
              <uri>model://turtlebotJde2cam/meshes/sonyvid30/sonyvid30_bottom.dae</uri>
              <scale>4.000000 3.000000 3.000000</scale>
            </mesh>
          </geometry>
        </visual>
        <collision name='collision'>
          <geometry>
            <box>
              <size>0.100000 0.100000 0.100000</size>
            </box>
          </geometry>
          <surface>
            <friction>
              <ode>
                <mu>100000.000000</mu>
                <mu2>100000.000000</mu2>
                <slip1>0.000000</slip1>
                <slip2>0.000000</slip2>
              </ode>
            </friction>
            <bounce/>
            <contact>
              <ode/>
            </contact>
          </surface>
          <max_contacts>10</max_contacts>
        </collision>
        <velocity_decay>
          <linear>0.000000</linear>
          <angular>0.000000</angular>
        </velocity_decay>
        <self_collide>0</self_collide>
        <kinematic>0</kinematic>
        <gravity>1</gravity>
      </link>
      <link name='camera_column_body_left'>
        <pose>-0.020000 0.076000 0.247400 -1.570000 0.000000 0.000000</pose>
        <inertial>
          <mass>0.500000</mass>
          <inertia>
            <ixx>1.000000</ixx>
            <ixy>0.000000</ixy>
            <ixz>0.000000</ixz>
            <iyy>1.000000</iyy>
            <iyz>0.000000</iyz>
            <izz>1.000000</izz>
          </inertia>
        </inertial>
        <visual name='visual'>
          <geometry>
            <mesh>
              <uri>model://turtlebotJde2cam/meshes/sonyvid30/sonyvid30_mid.dae</uri>
              <scale>0.600000 1.000000 1.000000</scale>
            </mesh>
          </geometry>
        </visual>
        <collision name='collision'>
          <geometry>
            <box>
              <size>0.100000 0.100000 0.100000</size>
            </box>
          </geometry>
          <surface>
            <friction>
              <ode>
                <mu>100000.000000</mu>
                <mu2>100000.000000</mu2>
                <slip1>0.000000</slip1>
                <slip2>0.000000</slip2>
              </ode>
            </friction>
            <bounce/>
            <contact>
              <ode/>
            </contact>
          </surface>
          <max_contacts>10</max_contacts>
        </collision>
        <velocity_decay>
          <linear>0.000000</linear>
          <angular>0.000000</angular>
        </velocity_decay>
        <self_collide>0</self_collide>
        <kinematic>0</kinematic>
        <gravity>1</gravity>
      </link>
      <link name='camera_top_body_left'>
        <pose>-0.050000 0.076000 0.242400 -1.570000 -0.000000 3.140000</pose>
        <inertial>
          <mass>0.500000</mass>
          <inertia>
            <ixx>1.000000</ixx>
            <ixy>0.000000</ixy>
            <ixz>0.000000</ixz>
            <iyy>1.000000</iyy>
            <iyz>0.000000</iyz>
            <izz>1.000000</izz>
          </inertia>
        </inertial>
        <sensor name='cam_turtlebot_left' type='camera'>
          <pose>0.000000 0.000000 0.000000 -1.570000 -0.000000 3.140000</pose>
          <update_rate>20.000000</update_rate>
          <camera name='__default__'>
            <horizontal_fov>1.570000</horizontal_fov>
            <image>
              <width>640</width>
              <height>480</height>
              <format>R8G8B8</format>
            </image>
            <clip>
              <near>0.300000</near>
              <far>15.000000</far>
            </clip>
          </camera>
          <plugin name='camera_dump' filename='libcamera_dumpTurtlebotJde.so'/>
        </sensor>
        <visual name='visual'>
          <geometry>
            <mesh>
              <uri>model://turtlebotJde2cam/meshes/sonyvid30/sonyvid30_top.dae</uri>
              <scale>2.000000 2.000000 1.300000</scale>
            </mesh>
          </geometry>
        </visual>
        <collision name='collision'>
          <geometry>
            <box>
              <size>0.100000 0.100000 0.100000</size>
            </box>
          </geometry>
          <surface>
            <friction>
              <ode>
                <mu>100000.000000</mu>
                <mu2>100000.000000</mu2>
                <slip1>0.000000</slip1>
                <slip2>0.000000</slip2>
              </ode>
            </friction>
            <bounce/>
            <contact>
              <ode/>
            </contact>
          </surface>
          <max_contacts>10</max_contacts>
        </collision>
        <velocity_decay>
          <linear>0.000000</linear>
          <angular>0.000000</angular>
        </velocity_decay>
        <self_collide>0</self_collide>
        <kinematic>0</kinematic>
        <gravity>1</gravity>
      </link>
      <link name='camera_bottom_body_right'>
        <pose>-0.030000 -0.076000 0.232400 -1.570000 0.000000 0.000000</pose>
        <inertial>
          <mass>0.500000</mass>
          <inertia>
            <ixx>1.000000</ixx>
            <ixy>0.000000</ixy>
            <ixz>0.000000</ixz>
            <iyy>1.000000</iyy>
            <iyz>0.000000</iyz>
            <izz>1.000000</izz>
          </inertia>
        </inertial>
        <visual name='visual'>
          <geometry>
            <mesh>
              <uri>model://turtlebotJde2cam/meshes/sonyvid30/sonyvid30_bottom.dae</uri>
              <scale>4.000000 3.000000 3.000000</scale>
            </mesh>
          </geometry>
        </visual>
        <collision name='collision'>
          <geometry>
            <box>
              <size>0.100000 0.100000 0.100000</size>
            </box>
          </geometry>
          <surface>
            <friction>
              <ode>
                <mu>100000.000000</mu>
                <mu2>100000.000000</mu2>
                <slip1>0.000000</slip1>
                <slip2>0.000000</slip2>
              </ode>
            </friction>
            <bounce/>
            <contact>
              <ode/>
            </contact>
          </surface>
          <max_contacts>10</max_contacts>
        </collision>
        <velocity_decay>
          <linear>0.000000</linear>
          <angular>0.000000</angular>
        </velocity_decay>
        <self_collide>0</self_collide>
        <kinematic>0</kinematic>
        <gravity>1</gravity>
      </link>
      <link name='camera_column_body_right'>
        <pose>-0.020000 -0.076000 0.247400 -1.570000 0.000000 0.000000</pose>
        <inertial>
          <mass>0.500000</mass>
          <inertia>
            <ixx>1.000000</ixx>
            <ixy>0.000000</ixy>
            <ixz>0.000000</ixz>
            <iyy>1.000000</iyy>
            <iyz>0.000000</iyz>
            <izz>1.000000</izz>
          </inertia>
        </inertial>
        <visual name='visual'>
          <geometry>
            <mesh>
              <uri>model://turtlebotJde2cam/meshes/sonyvid30/sonyvid30_mid.dae</uri>
              <scale>0.600000 1.000000 1.000000</scale>
            </mesh>
          </geometry>
        </visual>
        <collision name='collision'>
          <geometry>
            <box>
              <size>0.100000 0.100000 0.100000</size>
            </box>
          </geometry>
          <surface>
            <friction>
              <ode>
                <mu>100000.000000</mu>
                <mu2>100000.000000</mu2>
                <slip1>0.000000</slip1>
                <slip2>0.000000</slip2>
              </ode>
            </friction>
            <bounce/>
            <contact>
              <ode/>
            </contact>
          </surface>
          <max_contacts>10</max_contacts>
        </collision>
        <velocity_decay>
          <linear>0.000000</linear>
          <angular>0.000000</angular>
        </velocity_decay>
        <self_collide>0</self_collide>
        <kinematic>0</kinematic>
        <gravity>1</gravity>
      </link>
      <link name='camera_top_body_right'>
        <pose>-0.050000 -0.076000 0.242400 -1.570000 -0.000000 3.140000</pose>
        <inertial>
          <mass>0.500000</mass>
          <inertia>
            <ixx>1.000000</ixx>
            <ixy>0.000000</ixy>
            <ixz>0.000000</ixz>
            <iyy>1.000000</iyy>
            <iyz>0.000000</iyz>
            <izz>1.000000</izz>
          </inertia>
        </inertial>
        <sensor name='cam_turtlebot_right' type='camera'>
          <pose>0.000000 0.000000 0.000000 -1.570000 -0.000000 3.140000</pose>
          <update_rate>20.000000</update_rate>
          <camera name='__default__'>
            <horizontal_fov>1.570000</horizontal_fov>
            <image>
              <width>640</width>
              <height>480</height>
              <format>R8G8B8</format>
            </image>
            <clip>
              <near>0.300000</near>
              <far>15.000000</far>
            </clip>
          </camera>
          <plugin name='camera_dump' filename='libcamera_dumpTurtlebotJde.so'/>
        </sensor>
        <visual name='visual'>
          <geometry>
            <mesh>
              <uri>model://turtlebotJde2cam/meshes/sonyvid30/sonyvid30_top.dae</uri>
              <scale>2.000000 2.000000 1.300000</scale>
            </mesh>
          </geometry>
        </visual>
        <collision name='collision'>
          <geometry>
            <box>
              <size>0.100000 0.100000 0.100000</size>
            </box>
          </geometry>
          <surface>
            <friction>
              <ode>
                <mu>100000.000000</mu>
                <mu2>100000.000000</mu2>
                <slip1>0.000000</slip1>
                <slip2>0.000000</slip2>
              </ode>
            </friction>
            <bounce/>
            <contact>
              <ode/>
            </contact>
          </surface>
          <max_contacts>10</max_contacts>
        </collision>
        <velocity_decay>
          <linear>0.000000</linear>
          <angular>0.000000</angular>
        </velocity_decay>
        <self_collide>0</self_collide>
        <kinematic>0</kinematic>
        <gravity>1</gravity>
      </link>
      <link name='create::base'>
        <inertial>
          <pose>0.001453 -0.000453 0.029787 0.000000 0.000000 0.000000</pose>
          <inertia>
            <ixx>0.058640</ixx>
            <ixy>0.000124</ixy>
            <ixz>0.000615</ixz>
            <iyy>0.058786</iyy>
            <iyz>0.000014</iyz>
            <izz>1.532440</izz>
          </inertia>
          <mass>2.234000</mass>
        </inertial>
        <collision name='base_collision'>
          <pose>0.000000 0.000000 0.047800 0.000000 0.000000 0.000000</pose>
          <geometry>
            <cylinder>
              <radius>0.016495</radius>
              <length>0.061163</length>
            </cylinder>
          </geometry>
          <max_contacts>10</max_contacts>
          <surface>
            <bounce/>
            <friction>
              <ode/>
            </friction>
            <contact>
              <ode/>
            </contact>
          </surface>
        </collision>
<!--        <visual name='base_visual'>
          <pose>0.000000 0.000000 0.047800 0.000000 0.000000 0.000000</pose>
          <geometry>
            <mesh>
              <uri>model://createJde/meshes/create_body.dae</uri>
            </mesh>
          </geometry>
        </visual>-->
        <collision name='front_wheel_collision'>
          <pose>0.130000 0.000000 0.017000 -0.000000 1.570700 1.570700</pose>
          <geometry>
            <sphere>
              <radius>0.018000</radius>
            </sphere>
          </geometry>
          <surface>
            <friction>
              <ode>
                <mu>0.000000</mu>
                <mu2>0.000000</mu2>
                <fdir1>0.000000 0.000000 0.000000</fdir1>
                <slip1>0.000000</slip1>
                <slip2>0.000000</slip2>
              </ode>
            </friction>
            <bounce/>
            <contact>
              <ode/>
            </contact>
          </surface>
          <max_contacts>10</max_contacts>
        </collision>
        <visual name='front_wheel_visual'>
          <pose>0.130000 0.000000 0.017000 -0.000000 1.570700 1.570700</pose>
          <geometry>
            <sphere>
              <radius>0.009000</radius>
            </sphere>
          </geometry>
        </visual>
        <collision name='rear_wheel_collision'>
          <pose>-0.130000 0.000000 0.017000 -0.000000 1.570700 1.570700</pose>
          <geometry>
            <sphere>
              <radius>0.015000</radius>
            </sphere>
          </geometry>
          <surface>
            <friction>
              <ode>
                <mu>0.000000</mu>
                <mu2>0.000000</mu2>
                <fdir1>0.000000 0.000000 0.000000</fdir1>
                <slip1>0.000000</slip1>
                <slip2>0.000000</slip2>
              </ode>
            </friction>
            <bounce/>
            <contact>
              <ode/>
            </contact>
          </surface>
          <max_contacts>10</max_contacts>
        </collision>
        <visual name='rear_wheel_visual'>
          <pose>-0.130000 0.000000 0.017000 -0.000000 1.570700 1.570700</pose>
          <geometry>
            <sphere>
              <radius>0.007500</radius>
            </sphere>
          </geometry>
        </visual>
        <sensor name='left_cliff_sensor' type='ray'>
          <pose>0.070000 0.140000 0.027000 0.000000 1.570790 0.000000</pose>
          <ray>
            <scan>
              <horizontal>
                <samples>1</samples>
                <resolution>1.000000</resolution>
                <min_angle>0.000000</min_angle>
                <max_angle>0.000000</max_angle>
              </horizontal>
            </scan>
            <range>
              <min>0.010000</min>
              <max>0.040000</max>
              <resolution>0.100000</resolution>
            </range>
          </ray>
        </sensor>
        <sensor name='leftfront_cliff_sensor' type='ray'>
          <pose>0.150000 0.040000 0.027000 0.000000 1.570790 0.000000</pose>
          <ray>
            <scan>
              <horizontal>
                <samples>1</samples>
                <resolution>1.000000</resolution>
                <min_angle>0.000000</min_angle>
                <max_angle>0.000000</max_angle>
              </horizontal>
            </scan>
            <range>
              <min>0.010000</min>
              <max>0.040000</max>
              <resolution>0.100000</resolution>
            </range>
          </ray>
        </sensor>
        <sensor name='right_cliff_sensor' type='ray'>
          <pose>0.070000 -0.140000 0.027000 0.000000 1.570790 0.000000</pose>
          <ray>
            <scan>
              <horizontal>
                <samples>1</samples>
                <resolution>1.000000</resolution>
                <min_angle>0.000000</min_angle>
                <max_angle>0.000000</max_angle>
              </horizontal>
            </scan>
            <range>
              <min>0.010000</min>
              <max>0.040000</max>
              <resolution>0.100000</resolution>
            </range>
          </ray>
        </sensor>
        <sensor name='rightfront_cliff_sensor' type='ray'>
          <pose>0.150000 -0.040000 0.027000 0.000000 1.570790 0.000000</pose>
          <ray>
            <scan>
              <horizontal>
                <samples>1</samples>
                <resolution>1.000000</resolution>
                <min_angle>0.000000</min_angle>
                <max_angle>0.000000</max_angle>
              </horizontal>
            </scan>
            <range>
              <min>0.010000</min>
              <max>0.040000</max>
              <resolution>0.100000</resolution>
            </range>
          </ray>
        </sensor>
        <sensor name='wall_sensor' type='ray'>
          <pose>0.090000 -0.120000 0.059000 0.000000 0.000000 -1.000000</pose>
          <ray>
            <scan>
              <horizontal>
                <samples>1</samples>
                <resolution>1.000000</resolution>
                <min_angle>0.000000</min_angle>
                <max_angle>0.000000</max_angle>
              </horizontal>
            </scan>
            <range>
              <min>0.016000</min>
              <max>0.040000</max>
              <resolution>0.100000</resolution>
            </range>
          </ray>
        </sensor>
        <velocity_decay>
          <linear>0.000000</linear>
          <angular>0.000000</angular>
        </velocity_decay>
        <pose>0.000000 0.000000 0.000000 0.000000 0.000000 0.000000</pose>
        <self_collide>0</self_collide>
        <kinematic>0</kinematic>
        <gravity>1</gravity>
      </link>
      <link name='create::left_wheel'>
        <pose>0.000000 0.130000 0.032000 0.000000 0.000000 0.000000</pose>
        <inertial>
          <inertia>
            <ixx>0.001000</ixx>
            <ixy>0.000000</ixy>
            <ixz>0.000000</ixz>
            <iyy>0.001000</iyy>
            <iyz>0.000000</iyz>
            <izz>0.001000</izz>
          </inertia>
          <mass>0.010000</mass>
        </inertial>
        <collision name='collision'>
          <pose>0.000000 0.000000 0.000000 -0.000000 1.570700 1.570700</pose>
          <geometry>
            <cylinder>
              <radius>0.033000</radius>
              <length>0.023000</length>
            </cylinder>
          </geometry>
          <surface>
            <friction>
              <ode>
                <mu>10.000000</mu>
                <mu2>10.000000</mu2>
                <fdir1>0.000000 0.000000 0.000000</fdir1>
                <slip1>0.000000</slip1>
                <slip2>0.000000</slip2>
              </ode>
            </friction>
            <bounce/>
            <contact>
              <ode/>
            </contact>
          </surface>
          <max_contacts>10</max_contacts>
        </collision>
        <visual name='visual'>
          <pose>0.000000 0.000000 0.000000 -0.000000 1.570700 1.570700</pose>
          <geometry>
            <cylinder>
              <radius>0.033000</radius>
              <length>0.023000</length>
            </cylinder>
          </geometry>
        </visual>
        <velocity_decay>
          <linear>0.000000</linear>
          <angular>0.000000</angular>
        </velocity_decay>
        <self_collide>0</self_collide>
        <kinematic>0</kinematic>
        <gravity>1</gravity>
      </link>
      <link name='create::right_wheel'>
        <pose>0.000000 -0.130000 0.032000 0.000000 0.000000 0.000000</pose>
        <inertial>
          <inertia>
            <ixx>0.001000</ixx>
            <ixy>0.000000</ixy>
            <ixz>0.000000</ixz>
            <iyy>0.001000</iyy>
            <iyz>0.000000</iyz>
            <izz>0.001000</izz>
          </inertia>
          <mass>0.010000</mass>
        </inertial>
        <collision name='collision'>
          <pose>0.000000 0.000000 0.000000 -0.000000 1.570700 1.570700</pose>
          <geometry>
            <cylinder>
              <radius>0.033000</radius>
              <length>0.023000</length>
            </cylinder>
          </geometry>
          <surface>
            <friction>
              <ode>
                <mu>10.000000</mu>
                <mu2>10.000000</mu2>
                <fdir1>0.000000 0.000000 0.000000</fdir1>
                <slip1>0.000000</slip1>
                <slip2>0.000000</slip2>
              </ode>
            </friction>
            <bounce/>
            <contact>
              <ode/>
            </contact>
          </surface>
          <max_contacts>10</max_contacts>
        </collision>
        <visual name='visual'>
          <pose>0.000000 0.000000 0.000000 -0.000000 1.570700 1.570700</pose>
          <geometry>
            <cylinder>
              <radius>0.033000</radius>
              <length>0.023000</length>
            </cylinder>
          </geometry>
        </visual>
        <velocity_decay>
          <linear>0.000000</linear>
          <angular>0.000000</angular>
        </velocity_decay>
        <self_collide>0</self_collide>
        <kinematic>0</kinematic>
        <gravity>1</gravity>
      </link>
      <joint name='create::left_wheel_hinge' type='revolute'>
        <parent>create::base</parent>
        <child>create::left_wheel</child>
        <axis>
          <xyz>0.000000 1.000000 0.000000</xyz>
          <limit>
            <lower>-10000000000000000.000000</lower>
            <upper>10000000000000000.000000</upper>
          </limit>
        </axis>
      </joint>
      <joint name='create::right_wheel_hinge' type='revolute'>
        <parent>create::base</parent>
        <child>create::right_wheel</child>
        <axis>
          <xyz>0.000000 1.000000 0.000000</xyz>
          <limit>
            <lower>-10000000000000000.000000</lower>
            <upper>10000000000000000.000000</upper>
          </limit>
        </axis>
      </joint>
      <plugin name='motors' filename='libmotorsTurtlebotJde.so'>
        <left_joint>create::left_wheel_hinge</left_joint>
        <right_joint>create::right_wheel_hinge</right_joint>
        <torque>5</torque>
      </plugin>
      <plugin name='encoders' filename='libencodersTurtlebotJde.so'/>
      <link name='kinect_model::kinect'>
        <inertial>
          <mass>0.300000</mass>
          <inertia>
            <ixx>1.000000</ixx>
            <ixy>0.000000</ixy>
            <ixz>0.000000</ixz>
            <iyy>1.000000</iyy>
            <iyz>0.000000</iyz>
            <izz>1.000000</izz>
          </inertia>
        </inertial>
        <collision name='collision'>
          <geometry>
            <box>
              <size>0.073000 0.276000 0.072000</size>
            </box>
          </geometry>
          <max_contacts>10</max_contacts>
          <surface>
            <bounce/>
            <friction>
              <ode/>
            </friction>
            <contact>
              <ode/>
            </contact>
          </surface>
        </collision>
        <visual name='visual'>
          <geometry>
            <mesh>
              <uri>model://kinect/meshes/kinect.dae</uri>
            </mesh>
          </geometry>
        </visual>
        <sensor name='kinect_model::kinect' type='depth'>
          <update_rate>5.000000</update_rate>
          <camera name='__default__'>
            <horizontal_fov>1.047198</horizontal_fov>
            <image>
              <width>640</width>
              <height>480</height>
              <format>R8G8B8</format>
            </image>
            <clip>
              <near>0.050000</near>
              <far>3.000000</far>
            </clip>
          </camera>
          <plugin name='depth_camera_plugin' filename='libkinectPluginTurtlebotJde.so'/>
        </sensor>
        <velocity_decay>
          <linear>0.000000</linear>
          <angular>0.000000</angular>
        </velocity_decay>
        <pose>-0.087098 0.000000 0.303857 0.000000 0.000000 0.000000</pose>
        <self_collide>0</self_collide>
        <kinematic>0</kinematic>
        <gravity>1</gravity>
      </link>
      <joint name='create_rack' type='revolute'>
        <parent>create::base</parent>
        <child>rack</child>
        <axis>
          <xyz>0.000000 0.000000 1.000000</xyz>
          <limit>
            <lower>0.000000</lower>
            <upper>0.000000</upper>
          </limit>
        </axis>
      </joint>
      <joint name='kinect_rack' type='revolute'>
        <parent>kinect_model::kinect</parent>
        <child>rack</child>
        <axis>
          <xyz>0.000000 0.000000 1.000000</xyz>
          <limit>
            <lower>0.000000</lower>
            <upper>0.000000</upper>
          </limit>
        </axis>
      </joint>
      <joint name='joint_laser' type='revolute'>
        <parent>rack</parent>
        <child>laser</child>
        <axis>
          <xyz>0.000000 0.000000 0.000000</xyz>
          <limit>
            <lower>0.000000</lower>
            <upper>0.000000</upper>
          </limit>
        </axis>
      </joint>
      <joint name='pan_joint_left' type='revolute'>
        <pose>0.000000 0.000000 0.000000 0.000000 0.000000 0.000000</pose>
        <child>camera_bottom_body_left</child>
        <parent>camera_column_body_left</parent>
        <axis>
          <xyz>0.000000 1.000000 0.000000</xyz>
          <limit>
            <lower>0.000000</lower>
            <upper>0.000000</upper>
          </limit>
        </axis>
      </joint>
      <joint name='tilt_joint_left' type='revolute'>
        <pose>0.000000 0.000000 0.000000 0.000000 0.000000 0.000000</pose>
        <child>camera_column_body_left</child>
        <parent>camera_top_body_left</parent>
        <axis>
          <xyz>1.000000 0.000000 0.000000</xyz>
          <limit>
            <lower>0.000000</lower>
            <upper>0.000000</upper>
          </limit>
        </axis>
      </joint>
      <joint name='camera_left' type='revolute'>
        <pose>0.000000 0.000000 0.000000 0.000000 0.000000 0.000000</pose>
        <child>camera_bottom_body_left</child>
        <parent>rack</parent>
        <axis>
          <xyz>0.000000 0.000000 0.000000</xyz>
          <limit>
            <lower>0.000000</lower>
            <upper>0.000000</upper>
          </limit>
        </axis>
      </joint>
      <joint name='pan_joint_right' type='revolute'>
        <pose>0.000000 0.000000 0.000000 0.000000 0.000000 0.000000</pose>
        <child>camera_bottom_body_right</child>
        <parent>camera_column_body_right</parent>
        <axis>
          <xyz>0.000000 1.000000 0.000000</xyz>
          <limit>
            <lower>0.000000</lower>
            <upper>0.000000</upper>
          </limit>
        </axis>
      </joint>
      <joint name='tilt_joint_right' type='revolute'>
        <pose>0.000000 0.000000 0.000000 0.000000 0.000000 0.000000</pose>
        <child>camera_column_body_right</child>
        <parent>camera_top_body_right</parent>
        <axis>
          <xyz>1.000000 0.000000 0.000000</xyz>
          <limit>
            <lower>0.000000</lower>
            <upper>0.000000</upper>
          </limit>
        </axis>
      </joint>
      <joint name='camera_right' type='revolute'>
        <pose>0.000000 0.000000 0.000000 0.000000 0.000000 0.000000</pose>
        <child>camera_bottom_body_right</child>
        <parent>rack</parent>
        <axis>
          <xyz>0.000000 0.000000 0.000000</xyz>
          <limit>
            <lower>0.000000</lower>
            <upper>0.000000</upper>
          </limit>
        </axis>
      </joint>
      <plugin name='pose3dencoders' filename='libpose3dencodersTurtlebotJde.so'>
        <left_joint_pose3dencoders_pan>pan_joint_right</left_joint_pose3dencoders_pan>
        <left_joint_pose3dencoders_tilt>tilt_joint_right</left_joint_pose3dencoders_tilt>
        <right_joint_pose3dencoders_pan>pan_joint_left</right_joint_pose3dencoders_pan>
        <right_joint_pose3dencoders_tilt>tilt_joint_left</right_joint_pose3dencoders_tilt>
        <torque>5</torque>
      </plugin>
      <static>0</static>
    </model>

  <!--<model name="create">

    <link name="base">
      <inertial>
        <pose>0.001453 -0.000453 0.029787 0 0 0</pose>
        <inertia>
          <ixx>0.058640</ixx>
          <ixy>0.000124</ixy>
          <ixz>0.000615</ixz>
          <iyy>0.058786</iyy>
          <iyz>0.000014</iyz>
          <izz>1.532440</izz>
        </inertia>
        <mass>2.234000</mass>
      </inertial>

      <collision name="base_collision">
        <pose>0 0 0.047800 0 0 0</pose>
        <geometry>
          <cylinder>
            <radius>0.016495</radius>
            <length>0.061163</length>
          </cylinder>
        </geometry>
      </collision>
      <visual name="base_visual">
        <pose>0 0 0.047800 0 0 0</pose>
        <geometry>
          <mesh>
            <uri>model://create/meshes/create_body.dae</uri>
          </mesh>
        </geometry>
      </visual>

      <collision name="front_wheel_collision">
        <pose>0.130000 0 0.017000 0 1.570700 1.570700</pose>
        <geometry>
          <sphere>
            <radius>0.018000</radius>
          </sphere>
        </geometry>
        <surface>
          <friction>
            <ode>
              <mu>0</mu>
              <mu2>0</mu2>
              <fdir1>0 0 0</fdir1>
              <slip1>0</slip1>
              <slip2>0</slip2>
            </ode>
          </friction>
        </surface>
      </collision>
      <visual name="front_wheel_visual">
        <pose>0.130000 0 0.017000 0 1.570700 1.570700</pose>
        <geometry>
          <sphere>
            <radius>0.009000</radius>
          </sphere>
        </geometry>
      </visual>

      <collision name="rear_wheel_collision">
        <pose>-0.13 0 0.017 0 1.5707 1.5707</pose>
        <geometry>
          <sphere>
            <radius>0.015000</radius>
          </sphere>
        </geometry>
        <surface>
          <friction>
            <ode>
              <mu>0</mu>
              <mu2>0</mu2>
              <fdir1>0 0 0</fdir1>
              <slip1>0</slip1>
              <slip2>0</slip2>
            </ode>
          </friction>
        </surface>
      </collision>
      <visual name="rear_wheel_visual">
        <pose>-0.130000 0 0.017000 0 1.570700 1.570700</pose>
        <geometry>
          <sphere>
            <radius>0.007500</radius>
          </sphere>
        </geometry>
      </visual>


      <sensor name="left_cliff_sensor" type="ray">
        <pose>0.070000 0.140000 0.027000 0 1.570790 0</pose>
        <ray>
          <scan>
            <horizontal>
              <samples>1</samples>
              <resolution>1.000000</resolution>
              <min_angle>0</min_angle>
              <max_angle>0</max_angle>
            </horizontal>
          </scan>
          <range>
            <min>0.010000</min>
            <max>0.040000</max>
            <resolution>0.100000</resolution>
          </range>
        </ray>
      </sensor>

      <sensor name="leftfront_cliff_sensor" type="ray">
        <pose>0.150000 0.040000 0.027000 0 1.570790 0</pose>
        <ray>
          <scan>
            <horizontal>
              <samples>1</samples>
              <resolution>1.000000</resolution>
              <min_angle>0</min_angle>
              <max_angle>0</max_angle>
            </horizontal>
          </scan>
          <range>
            <min>0.010000</min>
            <max>0.040000</max>
            <resolution>0.100000</resolution>
          </range>
        </ray>
      </sensor>

      <sensor name="right_cliff_sensor" type="ray">
        <pose>0.070000 -0.140000 0.027000 0 1.570790 0</pose>
        <ray>
          <scan>
            <horizontal>
              <samples>1</samples>
              <resolution>1.000000</resolution>
              <min_angle>0</min_angle>
              <max_angle>0</max_angle>
            </horizontal>
          </scan>
          <range>
            <min>0.010000</min>
            <max>0.040000</max>
            <resolution>0.100000</resolution>
          </range>
        </ray>
      </sensor>

      <sensor name="rightfront_cliff_sensor" type="ray">
        <pose>0.150000 -0.040000 0.027000 0 1.570790 0</pose>
        <ray>
          <scan>
            <horizontal>
              <samples>1</samples>
              <resolution>1.000000</resolution>
              <min_angle>0</min_angle>
              <max_angle>0</max_angle>
            </horizontal>
          </scan>
          <range>
            <min>0.010000</min>
            <max>0.040000</max>
            <resolution>0.100000</resolution>
          </range>
        </ray>
      </sensor>

      <sensor name="wall_sensor" type="ray">
        <pose>0.090000 -0.120000 0.059000 0 0 -1.000000</pose>
        <ray>
          <scan>
            <horizontal>
              <samples>1</samples>
              <resolution>1.000000</resolution>
              <min_angle>0</min_angle>
              <max_angle>0</max_angle>
            </horizontal>
          </scan>
          <range>
            <min>0.016000</min>
            <max>0.040000</max>
            <resolution>0.100000</resolution>
          </range>
        </ray>
      </sensor>
    </link>


    <link name="left_wheel">
      <pose>0 0.130000 0.032000 0 0 0</pose>
      <inertial>
        <inertia>
          <ixx>0.001000</ixx>
          <ixy>0</ixy>
          <ixz>0</ixz>
          <iyy>0.001000</iyy>
          <iyz>0</iyz>
          <izz>0.001000</izz>
        </inertia>
        <mass>0.010000</mass>
      </inertial>
      <collision name="collision">
        <pose>0 0 0 0 1.570700 1.570700</pose>
        <geometry>
          <cylinder>
            <radius>0.033000</radius>
            <length>0.023000</length>
          </cylinder>
        </geometry>
        <surface>
          <friction>
            <ode>
              <mu>10</mu>
              <mu2>10</mu2>
              <fdir1>0 0 0</fdir1>
              <slip1>0</slip1>
              <slip2>0</slip2>
            </ode>
          </friction>
        </surface>
      </collision>
      <visual name="visual">
        <pose>0 0 0 0 1.570700 1.570700</pose>
        <geometry>
          <cylinder>
            <radius>0.033000</radius>
            <length>0.023000</length>
          </cylinder>
        </geometry>
      </visual>
    </link>

    <link name="right_wheel">
      <pose>0 -0.130000 0.032000 0 0 0</pose>
      <inertial>
        <inertia>
          <ixx>0.001000</ixx>
          <ixy>0</ixy>
          <ixz>0</ixz>
          <iyy>0.001000</iyy>
          <iyz>0</iyz>
          <izz>0.001000</izz>
        </inertia>
        <mass>0.010000</mass>
      </inertial>
      <collision name="collision">
        <pose>0 0 0 0 1.570700 1.570700</pose>
        <geometry>
          <cylinder>
            <radius>0.033000</radius>
            <length>0.023000</length>
          </cylinder>
        </geometry>
        <surface>
          <friction>
            <ode>
              <mu>10</mu>
              <mu2>10</mu2>
              <fdir1>0 0 0</fdir1>
              <slip1>0</slip1>
              <slip2>0</slip2>
            </ode>
          </friction>
        </surface>
      </collision>
      <visual name="visual">
        <pose>0 0 0 0 1.570700 1.570700</pose>
        <geometry>
          <cylinder>
            <radius>0.033000</radius>
            <length>0.023000</length>
          </cylinder>
        </geometry>
      </visual>
    </link>

    <joint name="left_wheel" type="revolute">
      <parent>base</parent>
      <child>left_wheel</child>
      <axis>
        <xyz>0 1 0</xyz>
      </axis>
    </joint>

    <joint name="right_wheel" type="revolute">
      <parent>base</parent>
      <child>right_wheel</child>
      <axis>
        <xyz>0 1 0</xyz>
      </axis>
    </joint>

  </model>-->
</sdf>
