<sdf version='1.6'>
  <world name='default'>
    <light name='sun' type='directional'>
      <cast_shadows>1</cast_shadows>
      <pose frame=''>0 0 10 0 -0 0</pose>
      <diffuse>0.8 0.8 0.8 1</diffuse>
      <specular>0.2 0.2 0.2 1</specular>
      <attenuation>
        <range>1000</range>
        <constant>0.9</constant>
        <linear>0.01</linear>
        <quadratic>0.001</quadratic>
      </attenuation>
      <direction>-0.5 0.1 -0.9</direction>
    </light>
    <gravity>0 0 -9.8</gravity>
    <magnetic_field>6e-06 2.3e-05 -4.2e-05</magnetic_field>
    <atmosphere type='adiabatic'/>
    <physics name='default_physics' default='0' type='ode'>
      <max_step_size>0.001</max_step_size>
      <real_time_factor>1</real_time_factor>
      <real_time_update_rate>1000</real_time_update_rate>
    </physics>
    <scene>
      <ambient>0.4 0.4 0.4 1</ambient>
      <background>0.7 0.7 0.7 1</background>
      <shadows>1</shadows>
    </scene>
    <spherical_coordinates>
      <surface_model>EARTH_WGS84</surface_model>
      <latitude_deg>0</latitude_deg>
      <longitude_deg>0</longitude_deg>
      <elevation>0</elevation>
      <heading_deg>0</heading_deg>
    </spherical_coordinates>
    <model name='circuitoMbot'>
      <static>1</static>
      <link name='link'>
        <collision name='collision'>
          <geometry>
            <plane>
              <normal>0 0 1</normal>
              <size>100 100</size>
            </plane>
          </geometry>
          <surface>
            <friction>
              <ode>
                <mu>100</mu>
                <mu2>50</mu2>
              </ode>
              <torsional>
                <ode/>
              </torsional>
            </friction>
            <contact>
              <ode/>
            </contact>
            <bounce/>
          </surface>
          <max_contacts>10</max_contacts>
        </collision>
        <visual name='visual'>
          <cast_shadows>0</cast_shadows>
          <geometry>
            <mesh>
              <uri>model://circuitoMBOT/meshes/circuitoMbot.dae</uri>
            </mesh>
          </geometry>
        </visual>
        <self_collide>0</self_collide>
        <kinematic>0</kinematic>
      </link>
      <pose frame=''>0.320305 0.037733 0 0 -0 0</pose>
    </model>
    <model name='mbot'>
      <link name='chasis'>
        <pose frame=''>0 0 0 0 -0 0</pose>
        <inertial>
          <mass>0.5</mass>
          <inertia>
            <ixx>1</ixx>
            <ixy>0</ixy>
            <iyy>1</iyy>
            <ixz>0</ixz>
            <iyz>0</iyz>
            <izz>1</izz>
          </inertia>
        </inertial>
        <collision name='collision'>
          <geometry>
            <mesh>
              <uri>model://mbot/meshes/chasis.dae</uri>
            </mesh>
          </geometry>
          <max_contacts>10</max_contacts>
          <surface>
            <contact>
              <ode/>
            </contact>
            <bounce/>
            <friction>
              <torsional>
                <ode/>
              </torsional>
              <ode/>
            </friction>
          </surface>
        </collision>
        <visual name='visual'>
          <geometry>
            <mesh>
              <uri>model://mbot/meshes/chasis.dae</uri>
            </mesh>
          </geometry>
        </visual>
        <self_collide>0</self_collide>
        <kinematic>0</kinematic>
      </link>
      <link name='us'>
        <pose frame=''>0 0 0 0 -0 0</pose>
        <inertial>
          <mass>0.05</mass>
          <inertia>
            <ixx>1</ixx>
            <ixy>0</ixy>
            <iyy>1</iyy>
            <ixz>0</ixz>
            <iyz>0</iyz>
            <izz>1</izz>
          </inertia>
        </inertial>
        <collision name='collision'>
          <geometry>
            <mesh>
              <uri>model://mbot/meshes/us_sensor.dae</uri>
            </mesh>
          </geometry>
          <max_contacts>10</max_contacts>
          <surface>
            <contact>
              <ode/>
            </contact>
            <bounce/>
            <friction>
              <torsional>
                <ode/>
              </torsional>
              <ode/>
            </friction>
          </surface>
        </collision>
        <visual name='visual'>
          <geometry>
            <mesh>
              <uri>model://mbot/meshes/us_sensor.dae</uri>
            </mesh>
          </geometry>
        </visual>
        <sensor name='sonar' type='sonar'>
          <pose frame=''>0.083 -0.004 0.058 0 -1.5707 0</pose>
          <sonar>
            <min>0.03</min>
            <max>4</max>
            <radius>0.01</radius>
          </sonar>
          <always_on>1</always_on>
          <update_rate>30</update_rate>
          <visualize>1</visualize>
        </sensor>
        <self_collide>0</self_collide>
        <kinematic>0</kinematic>
      </link>
      <link name='picam'>
        <pose frame=''>0 0 0 0 -0 0</pose>
        <inertial>
          <mass>0.05</mass>
          <inertia>
            <ixx>1</ixx>
            <ixy>0</ixy>
            <iyy>1</iyy>
            <ixz>0</ixz>
            <iyz>0</iyz>
            <izz>1</izz>
          </inertia>
        </inertial>
        <collision name='collision'>
          <geometry>
            <mesh>
              <uri>model://mbot/meshes/picam.dae</uri>
            </mesh>
          </geometry>
          <max_contacts>10</max_contacts>
          <surface>
            <contact>
              <ode/>
            </contact>
            <bounce/>
            <friction>
              <torsional>
                <ode/>
              </torsional>
              <ode/>
            </friction>
          </surface>
        </collision>
        <visual name='visual'>
          <geometry>
            <mesh>
              <uri>model://mbot/meshes/picam.dae</uri>
            </mesh>
          </geometry>
        </visual>
        <sensor name='picam' type='camera'>
          <pose frame=''>0.072 -0.007 0.083 0 -0 0</pose>
          <camera name='__default__'>
            <horizontal_fov>1.047</horizontal_fov>
            <image>
              <width>640</width>
              <height>480</height>
            </image>
            <clip>
              <near>0.1</near>
              <far>10</far>
            </clip>
          </camera>
          <always_on>1</always_on>
          <plugin name='camera_dump' filename='libcamera_dumpF1.so'/>
          <update_rate>30</update_rate>
        </sensor>
        <self_collide>0</self_collide>
        <kinematic>0</kinematic>
      </link>
      <link name='ir'>
        <pose frame=''>0 0 0 0 -0 0</pose>
        <inertial>
          <mass>0.05</mass>
          <inertia>
            <ixx>1</ixx>
            <ixy>0</ixy>
            <iyy>1</iyy>
            <ixz>0</ixz>
            <iyz>0</iyz>
            <izz>1</izz>
          </inertia>
        </inertial>
        <collision name='collision'>
          <geometry>
            <mesh>
              <uri>model://mbot/meshes/ir_sensor.dae</uri>
            </mesh>
          </geometry>
          <max_contacts>10</max_contacts>
          <surface>
            <contact>
              <ode/>
            </contact>
            <bounce/>
            <friction>
              <torsional>
                <ode/>
              </torsional>
              <ode/>
            </friction>
          </surface>
        </collision>
        <visual name='visual'>
          <geometry>
            <mesh>
              <uri>model://mbot/meshes/ir_sensor.dae</uri>
            </mesh>
          </geometry>
        </visual>
        <sensor name='irLeft' type='camera'>
          <pose frame=''>0.09 0.002 0.01 0 1.5707 0</pose>
          <camera name='__default__'>
            <horizontal_fov>1.047</horizontal_fov>
            <image>
              <width>2</width>
              <height>2</height>
            </image>
            <clip>
              <near>0.0001</near>
              <far>0.2</far>
            </clip>
          </camera>
          <always_on>1</always_on>
          <plugin name='camera_dump' filename='libcamera_dumpF1.so'/>
          <update_rate>30</update_rate>
        </sensor>
        <sensor name='irRight' type='camera'>
          <pose frame=''>0.09 -0.0011 0.01 0 1.5707 0</pose>
          <camera name='__default__'>
            <horizontal_fov>1.047</horizontal_fov>
            <image>
              <width>2</width>
              <height>2</height>
            </image>
            <clip>
              <near>0.01</near>
              <far>0.2</far>
            </clip>
          </camera>
          <always_on>1</always_on>
          <plugin name='camera_dump' filename='libcamera_dumpF1.so'/>
          <update_rate>30</update_rate>
        </sensor>
        <self_collide>0</self_collide>
        <kinematic>0</kinematic>
      </link>
      <link name='right_wheel'>
        <pose frame=''>-0.003 -0.049 0.032 0 -0 0</pose>
        <inertial>
          <mass>0.08</mass>
          <inertia>
            <ixx>1</ixx>
            <ixy>0</ixy>
            <iyy>1</iyy>
            <ixz>0</ixz>
            <iyz>0</iyz>
            <izz>1</izz>
          </inertia>
        </inertial>
        <collision name='collision'>
          <pose frame=''>0 0 0 0 -0 0</pose>
          <geometry>
            <mesh>
              <uri>model://mbot/meshes/right_wheel.dae</uri>
            </mesh>
          </geometry>
          <max_contacts>10</max_contacts>
          <surface>
            <contact>
              <ode/>
            </contact>
            <bounce/>
            <friction>
              <torsional>
                <ode/>
              </torsional>
              <ode/>
            </friction>
          </surface>
        </collision>
        <visual name='visual'>
          <geometry>
            <mesh>
              <uri>model://mbot/meshes/right_wheel.dae</uri>
            </mesh>
          </geometry>
        </visual>
        <self_collide>0</self_collide>
        <kinematic>0</kinematic>
      </link>
      <link name='left_wheel'>
        <pose frame=''>-0.003 0.041 0.032 0 -0 0</pose>
        <inertial>
          <mass>0.08</mass>
          <inertia>
            <ixx>1</ixx>
            <ixy>0</ixy>
            <iyy>1</iyy>
            <ixz>0</ixz>
            <iyz>0</iyz>
            <izz>1</izz>
          </inertia>
        </inertial>
        <collision name='collision'>
          <pose frame=''>0 0 0 0 -0 0</pose>
          <geometry>
            <mesh>
              <uri>model://mbot/meshes/left_wheel.dae</uri>
            </mesh>
          </geometry>
          <max_contacts>10</max_contacts>
          <surface>
            <contact>
              <ode/>
            </contact>
            <bounce/>
            <friction>
              <torsional>
                <ode/>
              </torsional>
              <ode/>
            </friction>
          </surface>
        </collision>
        <visual name='visual'>
          <geometry>
            <mesh>
              <uri>model://mbot/meshes/left_wheel.dae</uri>
            </mesh>
          </geometry>
        </visual>
        <self_collide>0</self_collide>
        <kinematic>0</kinematic>
      </link>
      <joint name='right_wheel_hinge' type='revolute'>
        <pose frame=''>0 0 0 0 -0 0</pose>
        <child>right_wheel</child>
        <parent>chasis</parent>
        <axis>
          <xyz>0 1 0</xyz>
          <use_parent_model_frame>0</use_parent_model_frame>
          <limit>
            <lower>-1e+16</lower>
            <upper>1e+16</upper>
          </limit>
          <dynamics>
            <spring_reference>0</spring_reference>
            <spring_stiffness>0</spring_stiffness>
          </dynamics>
        </axis>
      </joint>
      <joint name='left_wheel_hinge' type='revolute'>
        <pose frame=''>0 0 0 0 -0 0</pose>
        <child>left_wheel</child>
        <parent>chasis</parent>
        <axis>
          <xyz>0 1 0</xyz>
          <use_parent_model_frame>0</use_parent_model_frame>
          <limit>
            <lower>-1e+16</lower>
            <upper>1e+16</upper>
          </limit>
          <dynamics>
            <spring_reference>0</spring_reference>
            <spring_stiffness>0</spring_stiffness>
          </dynamics>
        </axis>
      </joint>
      <joint name='us_fix' type='revolute'>
        <pose frame=''>0 0 0 0 -0 0</pose>
        <child>us</child>
        <parent>chasis</parent>
        <axis>
          <xyz>0 0 0</xyz>
          <use_parent_model_frame>0</use_parent_model_frame>
          <limit>
            <lower>-1e+16</lower>
            <upper>1e+16</upper>
          </limit>
          <dynamics>
            <spring_reference>0</spring_reference>
            <spring_stiffness>0</spring_stiffness>
          </dynamics>
        </axis>
      </joint>
      <joint name='ir_fix' type='revolute'>
        <pose frame=''>0 0 0 0 -0 0</pose>
        <child>ir</child>
        <parent>chasis</parent>
        <axis>
          <xyz>0 0 0</xyz>
          <use_parent_model_frame>0</use_parent_model_frame>
          <limit>
            <lower>-1e+16</lower>
            <upper>1e+16</upper>
          </limit>
          <dynamics>
            <spring_reference>0</spring_reference>
            <spring_stiffness>0</spring_stiffness>
          </dynamics>
        </axis>
      </joint>
      <joint name='picam_fix' type='revolute'>
        <pose frame=''>0 0 0 0 -0 0</pose>
        <child>picam</child>
        <parent>chasis</parent>
        <axis>
          <xyz>0 0 0</xyz>
          <use_parent_model_frame>0</use_parent_model_frame>
          <limit>
            <lower>-1e+16</lower>
            <upper>1e+16</upper>
          </limit>
          <dynamics>
            <spring_reference>0</spring_reference>
            <spring_stiffness>0</spring_stiffness>
          </dynamics>
        </axis>
      </joint>
      <plugin name='carMotors' filename='libholoCarMotors.so'/>
      <pose frame=''>-0.232844 -0.05997 0 0 -0 0</pose>
    </model>
    <state world_name='default'>
      <sim_time>77 121000000</sim_time>
      <real_time>84 598836005</real_time>
      <wall_time>1516306198 802773123</wall_time>
      <iterations>77121</iterations>
      <model name='circuitoMbot'>
        <pose frame=''>0.288271 0.052602 0 0 -0 0</pose>
        <scale>1 1 1</scale>
        <link name='link'>
          <pose frame=''>0.288271 0.052602 0 0 -0 0</pose>
          <velocity>0 0 0 0 -0 0</velocity>
          <acceleration>0 0 0 0 -0 0</acceleration>
          <wrench>0 0 0 0 -0 0</wrench>
        </link>
      </model>
      <model name='mbot'>
        <pose frame=''>6e-06 0 0 0 0.00021 0</pose>
        <scale>1 1 1</scale>
        <link name='chasis'>
          <pose frame=''>6e-06 0 0 0 0.00021 0</pose>
          <velocity>2e-06 0 -2.6e-05 0 -0 0</velocity>
          <acceleration>-6e-06 0 -9.7996 2.3e-05 1e-06 0</acceleration>
          <wrench>-3e-06 0 -4.8998 0 -0 0</wrench>
        </link>
        <link name='ir'>
          <pose frame=''>6e-06 0 0 0 0.00021 0</pose>
          <velocity>2e-06 0 -2.7e-05 0 -0 0</velocity>
          <acceleration>1.4e-05 0 -9.80099 0 -0 0</acceleration>
          <wrench>1e-06 0 -0.490049 0 -0 0</wrench>
        </link>
        <link name='left_wheel'>
          <pose frame=''>-0.002987 0.041 0.032 0 -0.000154 0</pose>
          <velocity>2e-06 0 -3.4e-05 0 -0 0</velocity>
          <acceleration>0.000157 5e-06 -9.80733 2.2e-05 -0 0</acceleration>
          <wrench>1.3e-05 0 -0.784587 0 -0 0</wrench>
        </link>
        <link name='picam'>
          <pose frame=''>6e-06 0 0 0 0.00021 0</pose>
          <velocity>2e-06 0 -2.7e-05 0 -0 0</velocity>
          <acceleration>1.4e-05 0 -9.80099 0 -0 0</acceleration>
          <wrench>1e-06 0 -0.490049 0 -0 0</wrench>
        </link>
        <link name='right_wheel'>
          <pose frame=''>-0.002987 -0.049 0.032 0 9.3e-05 0</pose>
          <velocity>2e-06 0 -1.9e-05 0 -0 0</velocity>
          <acceleration>-0.000149 -5e-06 -9.79328 6e-06 -0 0</acceleration>
          <wrench>-1.2e-05 0 -0.783463 0 -0 0</wrench>
        </link>
        <link name='us'>
          <pose frame=''>6e-06 0 0 0 0.00021 0</pose>
          <velocity>2e-06 0 -2.7e-05 0 -0 0</velocity>
          <acceleration>1.4e-05 0 -9.80099 0 -0 1e-06</acceleration>
          <wrench>1e-06 0 -0.490049 0 -0 0</wrench>
        </link>
      </model>
      <light name='sun'>
        <pose frame=''>0 0 10 0 -0 0</pose>
      </light>
    </state>
    <gui fullscreen='0'>
      <camera name='user_camera'>
        <pose frame=''>1.5803 0.01427 0.122825 -0 0.001796 2.99219</pose>
        <view_controller>orbit</view_controller>
        <projection_type>perspective</projection_type>
      </camera>
    </gui>
  </world>
</sdf>
