<?xml version="1.0" ?>
<sdf version="1.3">
    <model name="pioneer2dx">

        <link name="chassis">
            <pose>0 0 0.16 0 0 0</pose>
            <inertial>
                <mass>15.0</mass>
          </inertial>
            <collision name="collision">
                <geometry>
                    <box>
                        <size>0.445 0.277 0.17</size>
                  </box>
              </geometry>
          </collision>
            <collision name="castor_collision">
                <pose>-0.200 0 -0.12 0 0 0</pose>
                <geometry>
                    <sphere>
                        <radius>0.04</radius>
                  </sphere>
              </geometry>
                <surface>
                    <friction>
                        <ode>
                            <mu>0</mu>
                            <mu2>0</mu2>
                            <slip1>1.0</slip1>
                            <slip2>1.0</slip2>
                      </ode>
                  </friction>
              </surface>
          </collision>
            <visual name="visual">
                <pose>0 0 0.04 0 0 0</pose>
                <geometry>
                    <mesh>
                        <uri>model://pioneer2dx/meshes/chassis.dae</uri>
                  </mesh>
              </geometry>
          </visual>
            <visual name="castor_visual">
                <pose>-0.200 0 -0.12 0 0 0</pose>
                <geometry>
                    <sphere>
                        <radius>0.04</radius>
                  </sphere>
              </geometry>
                <material>
                    <script>
                        <uri>file://media/materials/scripts/gazebo.material</uri>
                        <name>Gazebo/FlatBlack</name>
                  </script>
              </material>
          </visual>
      </link>
        <link name="right_wheel">
            <pose>0.1 -.17 0.11 0 1.5707 1.5707</pose>
            <inertial>
                <mass>0.1</mass>
          </inertial>
            <collision name="collision">
                <geometry>
                    <cylinder>
                        <radius>0.11</radius>
                        <length>0.05</length>
                  </cylinder>
              </geometry>
                <surface>
                    <friction>
                        <ode>
                            <mu>100000.0</mu>
                            <mu2>100000.0</mu2>
                            <slip1>0.0</slip1>
                            <slip2>0.0</slip2>
                      </ode>
                  </friction>
              </surface>
          </collision>
            <visual name="visual">
                <geometry>
                    <cylinder>
                        <radius>0.11</radius>
                        <length>0.05</length>
                  </cylinder>
              </geometry>
                <material>
                    <script>
                        <uri>file://media/materials/scripts/gazebo.material</uri>
                        <name>Gazebo/FlatBlack</name>
                  </script>
              </material>
          </visual>
      </link>
        <link name="left_wheel">
            <pose>0.1 .17 0.11 0 1.5707 1.5707</pose>
            <inertial>
                <mass>0.5</mass>
          </inertial>
            <collision name="collision">
                <geometry>
                    <cylinder>
                        <radius>0.11</radius>
                        <length>0.05</length>
                  </cylinder>
              </geometry>
                <surface>
                    <friction>
                        <ode>
                            <mu>100000.0</mu>
                            <mu2>100000.0</mu2>
                            <slip1>0.0</slip1>
                            <slip2>0.0</slip2>
                      </ode>
                  </friction>
              </surface>
          </collision>
            <visual name="visual">
                <geometry>
                    <cylinder>
                        <radius>0.11</radius>
                        <length>0.05</length>
                  </cylinder>
              </geometry>
                <material>
                    <script>
                        <uri>file://media/materials/scripts/gazebo.material</uri>
                        <name>Gazebo/FlatBlack</name>
                  </script>
              </material>
          </visual>
      </link>
        
        
        <link name="laser">
            <pose>0.22 .0 0.3 0 0 0</pose>

		  <gravity>false</gravity>
		  <inertial>
		    <mass>0.1</mass>
		</inertial>
		  <visual name="visual">
		    <geometry>
		      <mesh>
		        <uri>model://hokuyo/meshes/hokuyo.dae</uri>
		    </mesh>
		  </geometry>
		</visual>

		  <collision name="collision-base">
		    <pose>0 0 -0.0145 0 0 0</pose>
		    <geometry>
		      <box>
		        <size>0.05 0.05 0.041</size>
		    </box>
		  </geometry>
		</collision>

		  <collision name="collision-top">
		    <pose>0 0 0.0205 0 0 0</pose>
		    <geometry>
		      <cylinder>
		        <radius>0.021</radius>
		        <length>0.029</length>
		    </cylinder>
		  </geometry>
		</collision>


		  <sensor name="laser" type="ray">
          <update_rate>20</update_rate>
		    <ray>
		      <scan>
		        <horizontal>
		          <samples>180</samples>
		          <resolution>1</resolution>
		          <min_angle>-1.57</min_angle>
		          <max_angle>1.57</max_angle>
		      </horizontal>
		    </scan>
		      <range>
		        <min>0.08</min>
		        <max>10</max>
		        <resolution>0.01</resolution>
		    </range>
		  </ray>


		    <plugin name="laser" filename="liblaser.so" />
		    
		    <always_on>1</always_on>
		    <visualize>true</visualize>

		</sensor>
		</link>
        

      <link name="camera_bottom_body_left">
      	<pose>0.16 0.1 0.3 -1.57 0 0</pose>
            <inertial>
                <mass>0.5</mass>
          </inertial>
	 	 <visual name="visual">
            <geometry>
                <mesh>
                    <uri>model://pioneer2dxJde/meshes/sonyvid30/sonyvid30_bottom.dae</uri>
                    <scale>4 3 3</scale>
              </mesh>
          </geometry>
      </visual>

        <collision name="collision">
            <geometry>
                <box>
                    <size>0.1 0.1 0.1</size>
              </box>
          </geometry>
            <surface>
                <friction>
                    <ode>
                        <mu>100000.0</mu>
                        <mu2>100000.0</mu2>
                        <slip1>0.0</slip1>
                        <slip2>0.0</slip2>
                  </ode>
              </friction>
          </surface>
      </collision>
    </link>

      <link name="camera_column_body_left">
      
    	<pose>0.17 0.1 0.315 -1.57 0 0</pose>
        <inertial>
                <mass>0.5</mass>
      </inertial>
	 	<visual name="visual">
           <geometry>
               <mesh>
                   <uri>model://pioneer2dxJde/meshes/sonyvid30/sonyvid30_mid.dae</uri>
                   <scale>0.6 1 1</scale>
             </mesh>
         </geometry>
      </visual>

        <collision name="collision">
            <geometry>
                <box>
                    <size>0.1 0.1 0.1</size>
              </box>
          </geometry>
            <surface>
                <friction>
                    <ode>
                        <mu>100000.0</mu>
                        <mu2>100000.0</mu2>
                        <slip1>0.0</slip1>
                        <slip2>0.0</slip2>
                  </ode>
              </friction>
          </surface>
      </collision>

    </link>
      
    	<link name="camera_top_body_left">
        	<pose>0.14 0.1 0.31 -1.57 0 3.14</pose>
        <inertial>
                <mass>0.5</mass>
      </inertial>
        
        <sensor name='cam_pioneer_left' type='camera'>
        	<pose>0 0 0 -1.57 0 3.14</pose>
            <update_rate>20</update_rate>
            <camera>
              <horizontal_fov>1.57</horizontal_fov>
              <image>
              	<width>640</width>
              	<height>480</height>
              	<format>R8G8B8</format>
            </image>
              <clip>
		          <near>0.3</near>
		          <far>15</far>
            </clip>
          </camera>
            <plugin name='camera_dump' filename='libcamera_dump.so'/>
      </sensor>
            
	 	<visual name="visual">
           <geometry>
               <mesh>
                   <uri>model://pioneer2dxJde/meshes/sonyvid30/sonyvid30_top.dae</uri>
                   <scale>2 2 1.3</scale>
             </mesh>
         </geometry>
      </visual>

        <collision name="collision">
            <geometry>
                <box>
                    <size>0.1 0.1 0.1</size>
              </box>
          </geometry>
            <surface>
                <friction>
                    <ode>
                        <mu>100000.0</mu>
                        <mu2>100000.0</mu2>
                        <slip1>0.0</slip1>
                        <slip2>0.0</slip2>
                  </ode>
              </friction>
          </surface>
      </collision>

    </link>
      
            <link name="camera_bottom_body_right">
      	<pose>0.16 -0.1 0.3 -1.57 0 0</pose>
            <inertial>
                <mass>0.5</mass>
          </inertial>
	 	 <visual name="visual">
            <geometry>
                <mesh>
                    <uri>model://pioneer2dxJde/meshes/sonyvid30/sonyvid30_bottom.dae</uri>
                    <scale>4 3 3</scale>
              </mesh>
          </geometry>
      </visual>

        <collision name="collision">
            <geometry>
                <box>
                    <size>0.1 0.1 0.1</size>
              </box>
          </geometry>
            <surface>
                <friction>
                    <ode>
                        <mu>100000.0</mu>
                        <mu2>100000.0</mu2>
                        <slip1>0.0</slip1>
                        <slip2>0.0</slip2>
                  </ode>
              </friction>
          </surface>
      </collision>
    </link>

      <link name="camera_column_body_right">
      
    	<pose>0.17 -0.1 0.315 -1.57 0 0</pose>
        <inertial>
                <mass>0.5</mass>
      </inertial>
	 	<visual name="visual">
           <geometry>
               <mesh>
                   <uri>model://pioneer2dxJde/meshes/sonyvid30/sonyvid30_mid.dae</uri>
                   <scale>0.6 1 1</scale>
             </mesh>
         </geometry>
      </visual>

        <collision name="collision">
            <geometry>
                <box>
                    <size>0.1 0.1 0.1</size>
              </box>
          </geometry>
            <surface>
                <friction>
                    <ode>
                        <mu>100000.0</mu>
                        <mu2>100000.0</mu2>
                        <slip1>0.0</slip1>
                        <slip2>0.0</slip2>
                  </ode>
              </friction>
          </surface>
      </collision>

    </link>
      
    	<link name="camera_top_body_right">
        	<pose>0.14 -0.1 0.31 -1.57 0 3.14</pose>
        <inertial>
                <mass>0.5</mass>
      </inertial>
        
        <sensor name='cam_pioneer_right' type='camera'>
        	<pose>0 0 0 -1.57 0 3.14</pose>
            <update_rate>20</update_rate>
            <camera>
              <horizontal_fov>1.57</horizontal_fov>
              <image>
              	<width>640</width>
              	<height>480</height>
              	<format>R8G8B8</format>
            </image>
              <clip>
		          <near>0.3</near>
		          <far>15</far>
            </clip>
          </camera>
            <plugin name='camera_dump' filename='libcamera_dump.so'/>
      </sensor>
            
	 	<visual name="visual">
           <geometry>
               <mesh>
                   <uri>model://pioneer2dxJde/meshes/sonyvid30/sonyvid30_top.dae</uri>
                   <scale>2 2 1.3</scale>
             </mesh>
         </geometry>
      </visual>

        <collision name="collision">
            <geometry>
                <box>
                    <size>0.1 0.1 0.1</size>
              </box>
          </geometry>
            <surface>
                <friction>
                    <ode>
                        <mu>100000.0</mu>
                        <mu2>100000.0</mu2>
                        <slip1>0.0</slip1>
                        <slip2>0.0</slip2>
                  </ode>
              </friction>
          </surface>
      </collision>

    </link>
        <!--              JOINTS                         -->
		<joint type="revolute" name="pan_joint_right">
    		<pose>0 0 0 0 0 0</pose>
            <child>camera_bottom_body_right</child>
            <parent>camera_column_body_right</parent>
             <axis>
                <xyz>0 1 0</xyz>
                <limit>
                	<lower>0</lower>
                	<upper>0</upper>
              </limit>
          </axis>
		</joint>
		
		<joint type="revolute" name="tilt_joint_right">
    		<pose>0 0 0.0 0 0 0</pose>
            <child>camera_column_body_right</child>
            <parent>camera_top_body_right</parent>
             <axis>
                <xyz>1 0 0</xyz>
                <limit>
                	<lower>0</lower>
                	<upper>0</upper>
              </limit>
          </axis>
		</joint>   
		
        <joint type="revolute" name="camera_right">
            <pose>0 0 0. 0 0 0</pose>
            <child>camera_bottom_body_right</child>
            <parent>chassis</parent>
            <axis>
                <xyz>0 0 0</xyz>
                <limit>
                	<lower>0.0</lower>
                	<upper>0.0</upper>
              </limit>
          </axis>
      </joint>
        
      
        
		<joint type="revolute" name="pan_joint_left">
    		<pose>0 0 0 0 0 0</pose>
            <child>camera_bottom_body_left</child>
            <parent>camera_column_body_left</parent>
             <axis>
                <xyz>0 1 0</xyz>
                <limit>
                	<lower>0</lower>
                	<upper>0</upper>
              </limit>
          </axis>
		</joint>
		
		<joint type="revolute" name="tilt_joint_left">
    		<pose>0 0 0.0 0 0 0</pose>
            <child>camera_column_body_left</child>
            <parent>camera_top_body_left</parent>
             <axis>
                <xyz>1 0 0</xyz>
                <limit>
                	<lower>0</lower>
                	<upper>0</upper>
              </limit>
          </axis>
		</joint>   
		
        <joint type="revolute" name="camera_left">
            <pose>0 0 0 0 0 0</pose>
            <child>camera_bottom_body_left</child>
            <parent>chassis</parent>
            <axis>
                <xyz>0 0 0</xyz>
                <limit>
                	<lower>0.0</lower>
                	<upper>0.0</upper>
              </limit>
          </axis>
      </joint>
        
        
        <joint type="revolute" name="left_wheel_hinge">
            <pose>0 0 -0.03 0 0 0</pose>
            <child>left_wheel</child>
            <parent>chassis</parent>
            <axis>
                <xyz>0 1 0</xyz>
          </axis>
      </joint>
        <joint type="revolute" name="right_wheel_hinge">
            <pose>0 0 0.03 0 0 0</pose>
            <child>right_wheel</child>
            <parent>chassis</parent>
            <axis>
                <xyz>0 1 0</xyz>
          </axis>
      </joint>   
        
        <joint type="revolute" name="joint_laser">
            <parent>chassis</parent>
            <child>laser</child>
            <axis>
                <xyz>0 0 0</xyz>
                <limit>
                    <lower>0</lower>
                    <upper>0</upper>
              </limit>
          </axis>
      </joint>
        
        <plugin filename="libmotors.so" name="motors">
			<left_joint>left_wheel_hinge</left_joint>
			<right_joint>right_wheel_hinge</right_joint>
			<torque>5</torque>
		</plugin>

		<plugin filename="libpose3dencoders.so" name="pose3dencoders">
			<left_joint_pose3dencoders_pan>pan_joint_right</left_joint_pose3dencoders_pan>
			<left_joint_pose3dencoders_tilt>tilt_joint_right</left_joint_pose3dencoders_tilt>
			<right_joint_pose3dencoders_pan>pan_joint_left</right_joint_pose3dencoders_pan>
			<right_joint_pose3dencoders_tilt>tilt_joint_left</right_joint_pose3dencoders_tilt>
			<torque>5</torque>
		</plugin>
		
                <plugin filename="libpose3d_pioneer.so" name="pose3d_pioneer"/>
        
  </model>
</sdf>
