<?xml version='1.0'?>
<sdf version="1.5">
<model name="formula1">

	<plugin name="formula1plugin" filename="libformula1plugin.so">
   	      <bodyName>f1</bodyName>
   	      <iceConfigFile>formula1plugin.cfg</iceConfigFile>
      	  <drive_right_joint>rear_right_wheel_hinge</drive_right_joint>
      	  <drive_left_joint>rear_left_wheel_hinge</drive_left_joint>
		  <steering_right_joint>front_right_wheel_hinge</steering_right_joint>
		  <steering_left_joint>front_left_wheel_hinge</steering_left_joint>
		  <torque>5</torque>
    </plugin>

    <link name="f1">
    	<pose>0 0 0 0 0 0</pose>
    	<inertial>
          	<mass>10</mass>
          <inertia>
            <ixx>1</ixx>
          	<ixy>0</ixy>
          	<iyy>1</iyy>
          	<ixz>0</ixz>
          	<iyz>0</iyz>
          	<izz>1</izz>
          </inertia>
      	</inertial>
      	<collision name="collision">
          <geometry>
            <mesh>
              <uri>model://formula1/meshes/F1.dae</uri>
          	</mesh>
          </geometry>
       	</collision>
      	<visual name="visual">
          <geometry>
            <mesh>
              <uri>model://formula1/meshes/F1.dae</uri>
            </mesh>
          </geometry>
      	</visual>
    </link>

    <link name="front_right_wheel">
    	<pose>-0.16 0 0.06 0 1.57 0</pose>
          <inertial>
          	<mass>1.5</mass>
          <inertia>
            <ixx>0.002100875</ixx>
          	<ixy>0.0</ixy>
          	<iyy>0.002100875</iyy>
          	<ixz>0.0</ixz>
          	<iyz>0.0</iyz>
          	<izz>0.00297675</izz>
          </inertia>
      	</inertial>
        <collision name="collision">
          <geometry>
            <cylinder>
            	<radius>.063</radius>
            	<length>.07</length>
            </cylinder>
          </geometry>
        </collision>
        <visual name="visual">
          <geometry>
            <mesh>
              <uri>model://formula1/meshes/wheel.dae</uri>
          	</mesh>
          </geometry>
        </visual>
    </link>

    <link name="front_left_wheel">
        <pose>0.16 0 0.06 0 1.57 0</pose>
          <inertial>
        	<mass>1.5</mass>
          <inertia>
          	<ixx>0.002100875</ixx>
          	<ixy>0.0</ixy>
          	<iyy>0.002100875</iyy>
          	<ixz>0.0</ixz>
          	<iyz>0.0</iyz>
          	<izz>0.00297675</izz>
          </inertia>
      	</inertial>
        <collision name="collision">
          <geometry>
            <cylinder>
            	<radius>.063</radius>
            	<length>.07</length>
            </cylinder>
          </geometry>
        </collision>
        <visual name="visual">
          <geometry>
            <mesh>
              <uri>model://formula1/meshes/wheel.dae</uri>
          	</mesh>
          </geometry>
        </visual>
    </link>

    <link name="rear_left_wheel">
        <pose>0.16 0.58 0.06 0 1.57 0</pose>  <!-- rotation of 90 deg in y-axis, now x=-z y=y z=x take in count for the joints axis-->
          <inertial>
        	<mass>2</mass>
          <inertia>
          	<ixx>0.002801167</ixx>
          	<ixy>0.0</ixy>
          	<iyy>0.002801167</iyy>
          	<ixz>0.0</ixz>
          	<iyz>0.0</iyz>
          	<izz>0.003969</izz>
          </inertia>
        </inertial>
        <collision name="collision">
          <geometry>
            <cylinder>
            	<radius>.063</radius>
            	<length>.07</length>
            </cylinder>
          </geometry>
        </collision>
        <visual name="visual">
          <geometry>
            <mesh>
              <uri>model://formula1/meshes/wheel.dae</uri>
          	</mesh>
          </geometry>
        </visual>
    </link>
 
    <link name="rear_right_wheel">
        <pose>-0.16 0.58 0.06 0 1.57 0</pose>
          <inertial>
       		<mass>2</mass>
          <inertia>
          	<ixx>0.002801167</ixx>
          	<ixy>0.0</ixy>
          	<iyy>0.002801167</iyy>
          	<ixz>0.0</ixz>
          	<iyz>0.0</iyz>
          	<izz>0.003969</izz>
        </inertia>
        </inertial>
        <collision name="collision">
          <geometry>
            <cylinder>
            	<radius>.063</radius>
            	<length>.07</length>
            </cylinder>
          </geometry>
        </collision>
        <visual name="visual">
          <geometry>
            <mesh>
              <uri>model://formula1/meshes/wheel.dae</uri>
          	</mesh>
          </geometry>
        </visual>
    </link>

	<link name='camera_top_body_left'>
        <pose>0.050000 -0.09000 0.1442400 0.000000 -0.000000 0.000000</pose>
        <inertial>
          <mass>0.0500000</mass>
          <inertia>
          	<ixx>0.000002</ixx>
          	<ixy>0.0</ixy>
          	<iyy>0.000002</iyy>
          	<ixz>0.0</ixz>
          	<iyz>0.0</iyz>
          	<izz>0.000002</izz>
          </inertia>
        </inertial>
        <sensor name='cam_formula1_left' type='camera'>
          <pose>0.000000 0.000000 0.000000  0.00000 0.00000 -1.57000 </pose>
          <update_rate>20.000000</update_rate>
          <camera name='__default__'>
            <horizontal_fov>1.570000</horizontal_fov>
            <image>
              <width>640</width>
              <height>480</height>
              <format>R8G8B8</format>
            </image>
            <clip>
              <near>0.100000</near>
              <far>15.000000</far>
            </clip>
          </camera>
        </sensor>
        <visual name='visual'>
          <geometry>
			<sphere>
              <radius>.01</radius>
			</sphere>
          </geometry>
        </visual>
        <collision name='collision'>
          <geometry>
            <sphere>
              <radius>.01</radius>
			</sphere>
          </geometry>
          <max_contacts>10</max_contacts>
        </collision>
        <velocity_decay>
          <linear>0.000000</linear>
          <angular>0.000000</angular>
        </velocity_decay>
        <self_collide>0</self_collide>
        <kinematic>0</kinematic>
        <gravity>1</gravity>
    </link>

	<link name='camera_top_body_right'>
        <pose>-0.050000 -0.09000 0.1442400 0.000000 -0.000000 0.0000000</pose>
        <inertial>
          <mass>0.0500000</mass>
          <inertia>
          	<ixx>0.000002</ixx>
          	<ixy>0.0</ixy>
          	<iyy>0.000002</iyy>
          	<ixz>0.0</ixz>
          	<iyz>0.0</iyz>
          	<izz>0.000002</izz>
          </inertia>
          <inertia>
          </inertia>
        </inertial>
        <sensor name='cam_formula1_right' type='camera'>
          <pose>0.000000 0.000000 0.000000 0.000000 0.00000 -1.570000</pose>
          <update_rate>20.000000</update_rate>
          <camera name='__default__'>
            <horizontal_fov>1.570000</horizontal_fov>
            <image>
              <width>640</width>
              <height>480</height>
              <format>R8G8B8</format>
            </image>
            <clip>
              <near>0.100000</near>
              <far>15.000000</far>
            </clip>
          </camera>
        </sensor>
        <visual name='visual'>
          <geometry>
			<sphere>
              <radius>.01</radius>
			</sphere>
          </geometry>
        </visual>
        <collision name='collision'>
          <geometry>
            <sphere>
              <radius>.01</radius>
			</sphere>
          </geometry>
          <max_contacts>10</max_contacts>
        </collision>
        <velocity_decay>
          <linear>0.000000</linear>
          <angular>0.000000</angular>
        </velocity_decay>
        <self_collide>0</self_collide>
        <kinematic>0</kinematic>
        <gravity>1</gravity>
    </link>

	<link name='laser'>
        <pose>0.000000 -0.190000 0.072000 0.000000 0.000000 -1.570000</pose>
        <gravity>0</gravity>
        <inertial>
          <mass>0.0500000</mass>
		  <inertia>
          	<ixx>0.000000833</ixx>
          	<ixy>0.0</ixy>
          	<iyy>0.000000833</iyy>
          	<ixz>0.0</ixz>
          	<iyz>0.0</iyz>
          	<izz>0.000000833</izz>
          </inertia>
        </inertial>
        <visual name='visual'>
          <geometry>
            <mesh>
              <uri>model://formula1/meshes/hokuyo.dae</uri>
            </mesh>
          </geometry>
        </visual>
        <collision name='collision'>
          <geometry>
            <box>
            	<size>.01 .01 .01</size>
            </box>
          </geometry>
          <max_contacts>10</max_contacts>
        </collision>
        <sensor name='laser' type='ray'>
          <ray>
            <scan>
              <horizontal>
                <samples>180</samples>
                <resolution>1.000000</resolution>
                <min_angle>-1.570000</min_angle>
                <max_angle>1.570000</max_angle>
              </horizontal>
            </scan>
            <range>
              <min>0.080000</min>
              <max>10.000000</max>
              <resolution>0.010000</resolution>
            </range>
          </ray>
          <update_rate>20.000000</update_rate>
          <always_on>1</always_on>
          <visualize>1</visualize>
        </sensor>
        <velocity_decay>
          <linear>0.000000</linear>
          <angular>0.000000</angular>
        </velocity_decay>
        <self_collide>0</self_collide>
        <kinematic>0</kinematic>
    </link>
      
    <link name='steer_left'>
	  <pose>0.16 0 0.06 0 0 0</pose>
	  <inertial>
        	<mass>0.01</mass>
          <inertia>
          	<ixx>0.000004</ixx>
          	<ixy>0.0</ixy>
          	<iyy>0.000004</iyy>
          	<ixz>0.0</ixz>
          	<iyz>0.0</iyz>
          	<izz>0.000004</izz>
          </inertia>
        </inertial>
	  <collision name="collision">
      	<geometry>
          <sphere>
          	<radius>0.01</radius>
          </sphere>
        </geometry>
      </collision>
      <visual name="visual">
        <geometry>
          <sphere>
          	<radius>0.01</radius>
          </sphere>
        </geometry>
      </visual>
	</link>
	<link name='steer_right'>
		<inertial>
        	<mass>0.01</mass>
          <inertia>
          	<ixx>0.000004</ixx>
          	<ixy>0.0</ixy>
          	<iyy>0.000004</iyy>
          	<ixz>0.0</ixz>
          	<iyz>0.0</iyz>
          	<izz>0.000004</izz>
          </inertia>
        </inertial>
	  <pose>-0.16 0 0.06 0 0 0</pose>
		<collision name="collision">
          <geometry>
            <sphere>
              <radius>0.01</radius>
            </sphere>
          </geometry>
        </collision>
        <visual name="visual">
          <geometry>
            <sphere>
              <radius>0.01</radius>
            </sphere>
          </geometry>
        </visual>
	</link>

	<joint type="revolute" name="front_left_wheel_hinge">
	    <pose>0 0 0 0 0 0</pose>
	    <child>steer_left</child>
	    <parent>f1</parent>
	    <axis>
	      <xyz>0 0 -1</xyz>
	      <limit>
	      	<upper>0.349066</upper>
	      	<lower>-0.349066</lower>
	      </limit>
	    </axis>
	</joint>

    <joint type="revolute" name="front_right_wheel_hinge">
        <pose>0 0 0 0 0 0</pose>
        <child>steer_right</child>
        <parent>f1</parent>
        <axis>
          <xyz>0 0 -1</xyz>
          <limit>
	      	<upper>0.349066</upper>
	      	<lower>-0.349066</lower>
	      </limit>
        </axis>
    </joint>

    <joint type="revolute" name="front_left_wheel_hingex">
	    <pose>0 0 0 0 0 0</pose>
	    <child>front_left_wheel</child>
	    <parent>steer_left</parent>
	    <axis>
	      <xyz>0 0 1</xyz>
	    </axis>
	</joint>

    <joint type="revolute" name="front_right_wheel_hingex">
        <pose>0 0 0 0 0 0</pose>
        <child>front_right_wheel</child>
        <parent>steer_right</parent>
        <axis>
          <xyz>0 0 1</xyz>
        </axis>
    </joint>

   	<joint type="revolute" name="rear_left_wheel_hinge">
	    <pose>0 0 0 0 0 0</pose>
	    <child>rear_left_wheel</child>
	    <parent>f1</parent>
	    <axis>
	      <xyz>0 0 1</xyz>
	    </axis>
	</joint>

    <joint type="revolute" name="rear_right_wheel_hinge">
        <pose>0 0 0 0 0 0</pose>
        <child>rear_right_wheel</child>
        <parent>f1</parent>
        <axis>
          <xyz>0 0 1</xyz>
        </axis>
    </joint>

 	<joint type="revolute" name="camera_left">
        <pose>0 0 0 0 0 0</pose>
        <child>camera_top_body_left</child>
        <parent>f1</parent>
        <axis>
          <xyz>0 0 0</xyz>
        </axis>
    </joint>

	<joint type="revolute" name="camera_right">
        <pose>0 0 0 0 0 0</pose>
        <child>camera_top_body_right</child>
        <parent>f1</parent>
        <axis>
          <xyz>0 0 0</xyz>
        </axis>
    </joint>

	<joint type="revolute" name="laser_joint">
        <pose>0 0 0 0 0 0</pose>
        <child>laser</child>
        <parent>f1</parent>
        <axis>
          <xyz>0 0 0</xyz>
        </axis>
    </joint>
         
  </model>
</sdf>

