<sdf version='1.6'>
  <world name='default'>
    <model name='quadrotor'>
      <plugin name='ardroneplugin' filename='libquadrotorplugin2.so'>
        <alwaysOn>1</alwaysOn>
        <updateRate>10.0</updateRate>
        <bodyName>base_link</bodyName>
        <velocityXYLimit>3</velocityXYLimit>
        <velocityZLimit>5</velocityZLimit>
        <takeoffSpeed>3</takeoffSpeed>
        <takeoffCompletedAt>1.5</takeoffCompletedAt>
        <landSpeed>1</landSpeed>
        <landCompletedAt>0.2</landCompletedAt>
        <offset>0</offset>
        <drift>0.1</drift>
        <motionSmallNoise>0</motionSmallNoise>
        <motionDriftNoise>0</motionDriftNoise>
        <motionDriftNoiseTime>1.0</motionDriftNoiseTime>
        <rollpitchProportionalGain>10.0</rollpitchProportionalGain>
        <rollpitchDifferentialGain>5.0</rollpitchDifferentialGain>
        <rollpitchLimit>0.5</rollpitchLimit>
        <yawProportionalGain>2.0</yawProportionalGain>
        <yawDifferentialGain>1.0</yawDifferentialGain>
        <yawLimit>1.5</yawLimit>
        <velocityXYProportionalGain>5.0</velocityXYProportionalGain>
        <velocityXYDifferentialGain>1.0</velocityXYDifferentialGain>
        <velocityZProportionalGain>4.5</velocityZProportionalGain>
        <velocityZDifferentialGain>0.5</velocityZDifferentialGain>
        <velocityZIntegralGain>0.0</velocityZIntegralGain>
        <iceConfigFile>quadrotorplugin2.cfg</iceConfigFile>
      </plugin>
      <link name='base_link'>
        <gravity>1</gravity>
        <self_collide>0</self_collide>
        <kinematic>0</kinematic>
        <inertial>
          <mass>1.5</mass>
          <pose frame=''>0.00254 0 7.3e-05 0 -0 0</pose>
          <inertia>
            <ixx>0.013721</ixx>
            <ixy>0</ixy>
            <ixz>-2.3e-05</ixz>
            <iyy>0.014476</iyy>
            <iyz>0</iyz>
            <izz>0.024755</izz>
          </inertia>
        </inertial>
        <collision name='base_link_geom'>
          <laser_retro>0</laser_retro>
          <pose frame=''>0 0 0 0 -0 0</pose>
          <geometry>
            <mesh>
              <uri>model://ArDrone2/meshes/quadrotor/quadrotor_4.stl</uri>
            </mesh>
          </geometry>
          <surface>
            <friction>
              <ode>
                <mu>-1</mu>
                <mu2>-1</mu2>
                <fdir1>0 0 0</fdir1>
                <slip1>0</slip1>
                <slip2>0</slip2>
              </ode>
              <torsional>
                <ode/>
              </torsional>
            </friction>
            <bounce>
              <restitution_coefficient>0</restitution_coefficient>
              <threshold>100000</threshold>
            </bounce>
            <contact>
              <ode>
                <soft_cfm>0</soft_cfm>
                <soft_erp>0.2</soft_erp>
                <kp>1e+12</kp>
                <kd>1</kd>
                <max_vel>100</max_vel>
                <min_depth>0.001</min_depth>
              </ode>
            </contact>
          </surface>
          <max_contacts>10</max_contacts>
        </collision>
        <visual name='base_link_geom_visual'>
          <cast_shadows>1</cast_shadows>
          <laser_retro>0</laser_retro>
          <transparency>0</transparency>
          <geometry>
            <mesh>
              <uri>model://ArDrone2/meshes/quadrotor/quadrotor_4.dae</uri>
            </mesh>
          </geometry>
        </visual>
        <collision name='base_link_geom_ardrone_base_bottomcam'>
          <laser_retro>0</laser_retro>
          <pose frame=''>0.15 0 0 -0 -0 -1.5708</pose>
          <geometry>
            <box>
              <size>0.001 0.001 0.001</size>
            </box>
          </geometry>
          <surface>
            <friction>
              <ode>
                <mu>-1</mu>
                <mu2>-1</mu2>
                <fdir1>0 0 0</fdir1>
                <slip1>0</slip1>
                <slip2>0</slip2>
              </ode>
              <torsional>
                <ode/>
              </torsional>
            </friction>
            <bounce>
              <restitution_coefficient>0</restitution_coefficient>
              <threshold>100000</threshold>
            </bounce>
            <contact>
              <ode>
                <soft_cfm>0</soft_cfm>
                <soft_erp>0.2</soft_erp>
                <kp>1e+12</kp>
                <kd>1</kd>
                <max_vel>100</max_vel>
                <min_depth>0.001</min_depth>
              </ode>
            </contact>
          </surface>
          <max_contacts>10</max_contacts>
        </collision>
        <visual name='base_link_geom_ardrone_base_bottomcam_visual'>
          <cast_shadows>1</cast_shadows>
          <laser_retro>0</laser_retro>
          <transparency>0</transparency>
          <pose frame=''>0.15 0 -0 -0 -0 -1.5708</pose>
          <geometry>
            <box>
              <size>0.001 0.001 0.001</size>
            </box>
          </geometry>
        </visual>
        <collision name='base_link_geom_ardrone_base_frontcam'>
          <laser_retro>0</laser_retro>
          <pose frame=''>0.21 0 0.01 -1.5708 -0 -1.5708</pose>
          <geometry>
            <box>
              <size>0.001 0.001 0.001</size>
            </box>
          </geometry>
          <surface>
            <friction>
              <ode>
                <mu>-1</mu>
                <mu2>-1</mu2>
                <fdir1>0 0 0</fdir1>
                <slip1>0</slip1>
                <slip2>0</slip2>
              </ode>
              <torsional>
                <ode/>
              </torsional>
            </friction>
            <bounce>
              <restitution_coefficient>0</restitution_coefficient>
              <threshold>100000</threshold>
            </bounce>
            <contact>
              <ode>
                <soft_cfm>0</soft_cfm>
                <soft_erp>0.2</soft_erp>
                <kp>1e+12</kp>
                <kd>1</kd>
                <max_vel>100</max_vel>
                <min_depth>0.001</min_depth>
              </ode>
            </contact>
          </surface>
          <max_contacts>10</max_contacts>
        </collision>
        <visual name='base_link_geom_ardrone_base_frontcam_visual'>
          <cast_shadows>1</cast_shadows>
          <laser_retro>0</laser_retro>
          <transparency>0</transparency>
          <pose frame=''>0.21 -0 0.01 -1.5708 -0 -1.5708</pose>
          <geometry>
            <box>
              <size>0.001 0.001 0.001</size>
            </box>
          </geometry>
        </visual>
        <collision name='base_link_geom_bottom_link'>
          <laser_retro>0</laser_retro>
          <pose frame=''>0.15 0 0 -3.14159 -1.57079 -3.14159</pose>
          <geometry>
            <box>
              <size>0.01 0.01 0.01</size>
            </box>
          </geometry>
          <surface>
            <friction>
              <ode>
                <mu>-1</mu>
                <mu2>-1</mu2>
                <fdir1>0 0 0</fdir1>
                <slip1>0</slip1>
                <slip2>0</slip2>
              </ode>
              <torsional>
                <ode/>
              </torsional>
            </friction>
            <bounce>
              <restitution_coefficient>0</restitution_coefficient>
              <threshold>100000</threshold>
            </bounce>
            <contact>
              <ode>
                <soft_cfm>0</soft_cfm>
                <soft_erp>0.2</soft_erp>
                <kp>1e+12</kp>
                <kd>1</kd>
                <max_vel>100</max_vel>
                <min_depth>0.001</min_depth>
              </ode>
            </contact>
          </surface>
          <max_contacts>10</max_contacts>
        </collision>
        <visual name='base_link_geom_bottom_link_visual'>
          <cast_shadows>1</cast_shadows>
          <laser_retro>0</laser_retro>
          <transparency>0</transparency>
          <pose frame=''>0.15 0 0 3.14159 -1.57079 3.14159</pose>
          <geometry>
            <box>
              <size>0.01 0.01 0.01</size>
            </box>
          </geometry>
          <material>
            <script>
              <uri>__default__</uri>
              <name>__default__</name>
            </script>
          </material>
        </visual>
        <collision name='base_link_geom_front_link'>
          <laser_retro>0</laser_retro>
          <pose frame=''>0.21 0 0.01 0 -0 0</pose>
          <geometry>
            <box>
              <size>0.01 0.01 0.01</size>
            </box>
          </geometry>
          <surface>
            <friction>
              <ode>
                <mu>-1</mu>
                <mu2>-1</mu2>
                <fdir1>0 0 0</fdir1>
                <slip1>0</slip1>
                <slip2>0</slip2>
              </ode>
              <torsional>
                <ode/>
              </torsional>
            </friction>
            <bounce>
              <restitution_coefficient>0</restitution_coefficient>
              <threshold>100000</threshold>
            </bounce>
            <contact>
              <ode>
                <soft_cfm>0</soft_cfm>
                <soft_erp>0.2</soft_erp>
                <kp>1e+12</kp>
                <kd>1</kd>
                <max_vel>100</max_vel>
                <min_depth>0.001</min_depth>
              </ode>
            </contact>
          </surface>
          <max_contacts>10</max_contacts>
        </collision>
        <visual name='base_link_geom_front_link_visual'>
          <cast_shadows>1</cast_shadows>
          <laser_retro>0</laser_retro>
          <transparency>0</transparency>
          <pose frame=''>0.21 0 0.01 0 -0 0</pose>
          <geometry>
            <box>
              <size>0.01 0.01 0.01</size>
            </box>
          </geometry>
          <material>
            <script>
              <uri>__default__</uri>
              <name>__default__</name>
            </script>
          </material>
        </visual>
        <collision name='base_link_geom_sonar_link'>
          <laser_retro>0</laser_retro>
          <pose frame=''>-0.15 0 0 -3.14159 1.57079 -3.14159</pose>
          <geometry>
            <box>
              <size>0.01 0.01 0.01</size>
            </box>
          </geometry>
          <surface>
            <friction>
              <ode>
                <mu>-1</mu>
                <mu2>-1</mu2>
                <fdir1>0 0 0</fdir1>
                <slip1>0</slip1>
                <slip2>0</slip2>
              </ode>
              <torsional>
                <ode/>
              </torsional>
            </friction>
            <bounce>
              <restitution_coefficient>0</restitution_coefficient>
              <threshold>100000</threshold>
            </bounce>
            <contact>
              <ode>
                <soft_cfm>0</soft_cfm>
                <soft_erp>0.2</soft_erp>
                <kp>1e+12</kp>
                <kd>1</kd>
                <max_vel>100</max_vel>
                <min_depth>0.001</min_depth>
              </ode>
            </contact>
          </surface>
          <max_contacts>10</max_contacts>
        </collision>
        <visual name='base_link_geom_sonar_link_visual'>
          <cast_shadows>1</cast_shadows>
          <laser_retro>0</laser_retro>
          <transparency>0</transparency>
          <pose frame=''>-0.15 0 0 3.14159 1.57079 3.14159</pose>
          <geometry>
            <mesh>
              <uri>model://ArDrone2/meshes/sonar_sensor/max_sonar_ez4.dae</uri>
            </mesh>
          </geometry>
        </visual>
        <sensor name='cam_sensor_ventral' type='camera'>
          <always_on>0</always_on>
          <update_rate>60</update_rate>
          <visualize>0</visualize>
          <pose frame=''>0.15 0 0 0 1.57079 0</pose>
          <camera name='__default__'>
            <horizontal_fov>1.41372</horizontal_fov>
            <image>
              <width>320</width>
              <height>240</height>
              <format>R8G8B8</format>
            </image>
            <clip>
              <near>0.01</near>
              <far>100</far>
            </clip>
          </camera>
        </sensor>
        <sensor name='cam_sensor_frontal' type='camera'>
          <always_on>0</always_on>
          <update_rate>60</update_rate>
          <visualize>0</visualize>
          <pose frame=''>0.21 0 0.01 0 -0 0</pose>
          <camera name='__default__'>
            <horizontal_fov>1.41372</horizontal_fov>
            <image>
              <width>320</width>
              <height>240</height>
              <format>R8G8B8</format>
            </image>
            <clip>
              <near>0.01</near>
              <far>100</far>
            </clip>
          </camera>
        </sensor>
        <sensor name='sonar' type='ray'>
          <always_on>0</always_on>
          <update_rate>10</update_rate>
          <visualize>0</visualize>
          <pose frame=''>-0.15 0 0 -3.14159 1.57079 -3.14159</pose>
          <ray>
            <scan>
              <horizontal>
                <samples>3</samples>
                <resolution>1</resolution>
                <min_angle>-0.349066</min_angle>
                <max_angle>0.349066</max_angle>
              </horizontal>
              <vertical>
                <samples>3</samples>
                <resolution>1</resolution>
                <min_angle>-0.349066</min_angle>
                <max_angle>0.349066</max_angle>
              </vertical>
            </scan>
            <range>
              <min>0.01</min>
              <max>3</max>
              <resolution>0.01</resolution>
            </range>
          </ray>
        </sensor>
        <sensor name='imu_sensor' type='imu'>
          <update_rate>20</update_rate>
        </sensor>
      </link>
      <pose frame=''>0 0 0.5 0 -0 0</pose>
    </model>
    <light name='sun' type='directional'>
      <cast_shadows>1</cast_shadows>
      <pose frame=''>0 0 10 0 -0 0</pose>
      <diffuse>0.8 0.8 0.8 1</diffuse>
      <specular>0.1 0.1 0.1 1</specular>
      <attenuation>
        <range>1000</range>
        <constant>0.9</constant>
        <linear>0.01</linear>
        <quadratic>0.001</quadratic>
      </attenuation>
      <direction>-0.5 0.5 -1</direction>
    </light>
    <gravity>0 0 -9.8</gravity>
    <magnetic_field>6e-06 2.3e-05 -4.2e-05</magnetic_field>
    <atmosphere type='adiabatic'/>
    <physics name='default_physics' default='0' type='ode'>
      <max_step_size>0.001</max_step_size>
      <real_time_factor>1</real_time_factor>
      <real_time_update_rate>1000</real_time_update_rate>
    </physics>
    <scene>
      <ambient>0.4 0.4 0.4 1</ambient>
      <background>0.7 0.7 0.7 1</background>
      <shadows>1</shadows>
    </scene>
    <spherical_coordinates>
      <surface_model>EARTH_WGS84</surface_model>
      <latitude_deg>0</latitude_deg>
      <longitude_deg>0</longitude_deg>
      <elevation>0</elevation>
      <heading_deg>0</heading_deg>
    </spherical_coordinates>
    <model name='grass_plane'>
      <static>1</static>
      <link name='link'>
        <collision name='collision'>
          <geometry>
            <plane>
              <normal>0 0 1</normal>
              <size>250 250</size>
            </plane>
          </geometry>
          <surface>
            <friction>
              <ode>
                <mu>0.5</mu>
                <mu2>0.5</mu2>
              </ode>
              <torsional>
                <ode/>
              </torsional>
            </friction>
            <contact>
              <ode/>
            </contact>
            <bounce/>
          </surface>
          <max_contacts>10</max_contacts>
        </collision>
        <visual name='visual_0'>
          <pose frame=''>0 0 0 0 -0 0</pose>
          <cast_shadows>0</cast_shadows>
          <geometry>
            <plane>
              <normal>0 0 1</normal>
              <size>250 250</size>
            </plane>
          </geometry>
          <material>
            <script>
              <uri>model://grass_plane/materials/scripts</uri>
              <uri>model://grass_plane/materials/textures</uri>
              <name>vrc/grass</name>
            </script>
          </material>
        </visual>
        <self_collide>0</self_collide>
        <kinematic>0</kinematic>
      </link>
      <pose frame=''>0.224615 -1.66873 0 0 -0 0</pose>
    </model>
    <model name='logoJdeRobot'>
      <static>1</static>
      <link name='link'>
        <collision name='collision'>
          <geometry>
            <plane>
              <normal>0 0 1</normal>
              <size>1 1</size>
            </plane>
          </geometry>
          <surface>
            <friction>
              <ode>
                <mu>0.5</mu>
                <mu2>0.5</mu2>
              </ode>
              <torsional>
                <ode/>
              </torsional>
            </friction>
            <contact>
              <ode/>
            </contact>
            <bounce/>
          </surface>
          <max_contacts>10</max_contacts>
        </collision>
        <visual name='visual_0'>
          <pose frame=''>0 0 0.1 0 -0 0</pose>
          <cast_shadows>0</cast_shadows>
          <geometry>
            <plane>
              <normal>0 0 1</normal>
              <size>4 4</size>
            </plane>
          </geometry>
          <material>
            <script>
              <uri>model://logoJdeRobot/materials/scripts</uri>
              <uri>model://logoJdeRobot/materials/textures</uri>
              <name>vrc/logoJdeRobot</name>
            </script>
          </material>
        </visual>
        <self_collide>0</self_collide>
        <kinematic>0</kinematic>
      </link>
      <pose frame=''>-5.4041 0.171664 0 0 -0 0</pose>
    </model>
    <state world_name='default'>
      <sim_time>108 225000000</sim_time>
      <real_time>42 701741545</real_time>
      <wall_time>1514907730 860289646</wall_time>
      <iterations>24169</iterations>
      <model name='carColorBeacon'>
        <pose frame=''>3.71898 0.470689 0.000849 -0.000677 -3e-06 -0.000499</pose>
        <scale>1 1 1</scale>
        <link name='car'>
          <pose frame=''>3.71898 0.471197 0.750594 -0.000677 -3e-06 -0.000499</pose>
          <velocity>-0.0009 -0.001541 0.005141 0.0021 -0.001183 -9e-06</velocity>
          <acceleration>-0.899902 -1.53774 10.2811 2.10004 -1.18256 -0.009186</acceleration>
          <wrench>-0.899902 -1.53774 10.2811 0 -0 0</wrench>
        </link>
        <link name='front_left_steering_wheel_block'>
          <pose frame=''>2.61814 -1.22846 0.450015 -1.43353 1.57009 -1.43415</pose>
          <velocity>-6.6e-05 -0.001217 0.00387 -0.00281 -0.000768 -0.000533</velocity>
          <acceleration>-0.066503 -1.2138 9.00972 -2.81027 -0.767759 -0.533202</acceleration>
          <wrench>-0.066503 -1.2138 9.00972 0 -0 0</wrench>
        </link>
        <link name='front_left_wheel'>
          <pose frame=''>2.61814 -1.22846 0.450014 1.53833 1.56789 1.53771</pose>
          <velocity>-0.000115 -0.001226 0.003793 0.002533 -0.000269 -0.000566</velocity>
          <acceleration>-0.115387 -1.22211 8.93306 1.26635 -0.268575 -1.13214</acceleration>
          <wrench>-1.38465 -14.6654 107.197 0 -0 0</wrench>
        </link>
        <link name='front_right_steering_wheel_block'>
          <pose frame=''>4.81813 -1.22955 0.450014 -1.42656 1.57009 -1.42704</pose>
          <velocity>-0.000474 -0.000941 0.005357 -0.001998 -0.001531 -0.000422</velocity>
          <acceleration>-0.474504 -0.937551 10.4969 -1.99816 -1.53106 -0.422411</acceleration>
          <wrench>-0.474504 -0.937551 10.4969 0 -0 0</wrench>
        </link>
        <link name='front_right_wheel'>
          <pose frame=''>4.81813 -1.22955 0.450015 1.52645 1.56856 1.52598</pose>
          <velocity>-0.000487 -0.000988 0.00545 0.002044 -0.001098 -0.000458</velocity>
          <acceleration>-0.48714 -0.985001 10.5898 1.02174 -1.09756 -0.916136</acceleration>
          <wrench>-5.84568 -11.82 127.077 0 -0 0</wrench>
        </link>
        <link name='rear_left_wheel'>
          <pose frame=''>4.81961 1.71274 0.447969 1.47685 1.56967 1.47636</pose>
          <velocity>0.000354 -0.000521 0.000501 2e-06 -0.002281 0.000365</velocity>
          <acceleration>0.3538 -0.517431 5.64124 -3.14136 -0.860688 -2.41219</acceleration>
          <wrench>4.24561 -6.20917 67.6949 0 -0 0</wrench>
        </link>
        <link name='rear_right_wheel'>
          <pose frame=''>2.6196 1.71384 0.447977 1.42477 1.57002 1.42427</pose>
          <velocity>-0.000246 0.00028 0.0009 -2e-06 -0.003608 -0.00024</velocity>
          <acceleration>-0.246301 0.283426 6.04003 3.13974 0.466478 2.66121</acceleration>
          <wrench>-2.95561 3.40111 72.4804 0 -0 0</wrench>
        </link>
      </model>
      <model name='grass_plane'>
        <pose frame=''>0.224615 -1.66873 0 0 -0 0</pose>
        <scale>1 1 1</scale>
        <link name='link'>
          <pose frame=''>0.224615 -1.66873 0 0 -0 0</pose>
          <velocity>0 0 0 0 -0 0</velocity>
          <acceleration>0 0 0 0 -0 0</acceleration>
          <wrench>0 0 0 0 -0 0</wrench>
        </link>
      </model>
      <model name='logoJdeRobot'>
        <pose frame=''>-5.4041 0.171664 0 0 -0 0</pose>
        <scale>1 1 1</scale>
        <link name='link'>
          <pose frame=''>-5.4041 0.171664 0 0 -0 0</pose>
          <velocity>0 0 0 0 -0 0</velocity>
          <acceleration>0 0 0 0 -0 0</acceleration>
          <wrench>0 0 0 0 -0 0</wrench>
        </link>
      </model>
      <model name='quadrotor'>
        <pose frame=''>0.004972 -0.006954 0.039952 1.8e-05 0.000381 -0.029082</pose>
        <scale>1 1 1</scale>
        <link name='base_link'>
          <pose frame=''>0.004972 -0.006954 0.039952 1.8e-05 0.000381 -0.029082</pose>
          <velocity>0 0 0 0 -0 0</velocity>
          <acceleration>0 0 0 0 -0 0</acceleration>
          <wrench>0 0 0 0 -0 0</wrench>
        </link>
      </model>
      <light name='sun'>
        <pose frame=''>0 0 10 0 -0 0</pose>
      </light>
    </state>
    <gui fullscreen='0'>
      <camera name='user_camera'>
        <pose frame=''>14.0413 -11.0586 5.57212 0 0.275643 2.35619</pose>
        <view_controller>orbit</view_controller>
        <projection_type>perspective</projection_type>
      </camera>
    </gui>
    <model name='carColorBeacon'>
      <pose frame=''>3.71813 0.471628 0 0 -0 0</pose>
      <static>0</static>
      <link name='car'>
        <pose frame=''>0 0 0.749745 0 -0 0</pose>
        <collision name='collision'>
          <geometry>
            <mesh>
              <uri>model://carColorBeacon/meshes/model.dae</uri>
            </mesh>
          </geometry>
          <max_contacts>10</max_contacts>
          <surface>
            <contact>
              <ode/>
            </contact>
            <bounce/>
            <friction>
              <torsional>
                <ode/>
              </torsional>
              <ode/>
            </friction>
          </surface>
        </collision>
        <visual name='visual'>
          <geometry>
            <mesh>
              <uri>model://carColorBeacon/meshes/model.dae</uri>
            </mesh>
          </geometry>
        </visual>
        <self_collide>0</self_collide>
        <inertial>
          <inertia>
            <ixx>1</ixx>
            <ixy>0</ixy>
            <ixz>0</ixz>
            <iyy>1</iyy>
            <iyz>0</iyz>
            <izz>1</izz>
          </inertia>
          <mass>1</mass>
        </inertial>
        <kinematic>0</kinematic>
      </link>
      <link name='front_right_wheel'>
        <pose frame=''>1.1 -1.7 0.448 0 1.5707 0</pose>
        <inertial>
          <mass>12</mass>
          <inertia>
            <ixx>0.5</ixx>
            <ixy>0</ixy>
            <iyy>0.5</iyy>
            <ixz>0</ixz>
            <iyz>0</iyz>
            <izz>1</izz>
          </inertia>
        </inertial>
        <collision name='collision'>
          <geometry>
            <cylinder>
              <radius>0.45</radius>
              <length>0.3</length>
            </cylinder>
          </geometry>
          <max_contacts>10</max_contacts>
          <surface>
            <contact>
              <ode/>
            </contact>
            <bounce/>
            <friction>
              <torsional>
                <ode/>
              </torsional>
              <ode/>
            </friction>
          </surface>
        </collision>
        <self_collide>0</self_collide>
        <kinematic>0</kinematic>
      </link>
      <link name='front_left_wheel'>
        <pose frame=''>-1.1 -1.7 0.448 0 1.5707 0</pose>
        <inertial>
          <mass>12</mass>
          <inertia>
            <ixx>0.5</ixx>
            <ixy>0</ixy>
            <iyy>0.5</iyy>
            <ixz>0</ixz>
            <iyz>0</iyz>
            <izz>1</izz>
          </inertia>
        </inertial>
        <collision name='collision'>
          <geometry>
            <cylinder>
              <radius>0.45</radius>
              <length>0.3</length>
            </cylinder>
          </geometry>
          <max_contacts>10</max_contacts>
          <surface>
            <contact>
              <ode/>
            </contact>
            <bounce/>
            <friction>
              <torsional>
                <ode/>
              </torsional>
              <ode/>
            </friction>
          </surface>
        </collision>
        <self_collide>0</self_collide>
        <kinematic>0</kinematic>
      </link>
      <link name='front_left_steering_wheel_block'>
        <pose frame=''>-1.1 -1.7 0.448 0 1.5707 0</pose>
        <inertial>
          <mass>1</mass>
          <inertia>
            <ixx>1</ixx>
            <ixy>0</ixy>
            <iyy>1</iyy>
            <ixz>0</ixz>
            <iyz>0</iyz>
            <izz>1</izz>
          </inertia>
        </inertial>
        <collision name='collision'>
          <geometry>
            <cylinder>
              <radius>0.05</radius>
              <length>0.1</length>
            </cylinder>
          </geometry>
          <max_contacts>10</max_contacts>
          <surface>
            <contact>
              <ode/>
            </contact>
            <bounce/>
            <friction>
              <torsional>
                <ode/>
              </torsional>
              <ode/>
            </friction>
          </surface>
        </collision>
        <self_collide>0</self_collide>
        <kinematic>0</kinematic>
      </link>
      <link name='front_right_steering_wheel_block'>
        <pose frame=''>1.1 -1.7 0.448 0 1.5707 0</pose>
        <inertial>
          <mass>1</mass>
          <inertia>
            <ixx>1</ixx>
            <ixy>0</ixy>
            <iyy>1</iyy>
            <ixz>0</ixz>
            <iyz>0</iyz>
            <izz>1</izz>
          </inertia>
        </inertial>
        <collision name='collision'>
          <geometry>
            <cylinder>
              <radius>0.05</radius>
              <length>0.1</length>
            </cylinder>
          </geometry>
          <max_contacts>10</max_contacts>
          <surface>
            <contact>
              <ode/>
            </contact>
            <bounce/>
            <friction>
              <torsional>
                <ode/>
              </torsional>
              <ode/>
            </friction>
          </surface>
        </collision>
        <self_collide>0</self_collide>
        <kinematic>0</kinematic>
      </link>
      <link name='rear_left_wheel'>
        <pose frame=''>1.1 1.24229 0.448 0 1.5707 0</pose>
        <inertial>
          <mass>12</mass>
          <inertia>
            <ixx>0.5</ixx>
            <ixy>0</ixy>
            <iyy>0.5</iyy>
            <ixz>0</ixz>
            <iyz>0</iyz>
            <izz>1</izz>
          </inertia>
        </inertial>
        <collision name='collision'>
          <geometry>
            <cylinder>
              <radius>0.45</radius>
              <length>0.3</length>
            </cylinder>
          </geometry>
          <max_contacts>1</max_contacts>
          <surface>
            <friction>
              <ode>
                <mu>1</mu>
                <mu2>1</mu2>
                <fdir1>0 0 1</fdir1>
                <slip1>0</slip1>
                <slip2>0</slip2>
              </ode>
              <torsional>
                <ode/>
              </torsional>
            </friction>
            <contact>
              <ode>
                <min_depth>0.005</min_depth>
                <kp>1e+08</kp>
              </ode>
            </contact>
            <bounce/>
          </surface>
        </collision>
        <self_collide>0</self_collide>
        <kinematic>0</kinematic>
      </link>
      <link name='rear_right_wheel'>
        <pose frame=''>-1.1 1.24229 0.448 0 1.5707 0</pose>
        <inertial>
          <mass>12</mass>
          <inertia>
            <ixx>0.5</ixx>
            <ixy>0</ixy>
            <iyy>0.5</iyy>
            <ixz>0</ixz>
            <iyz>0</iyz>
            <izz>1</izz>
          </inertia>
        </inertial>
        <collision name='collision'>
          <geometry>
            <cylinder>
              <radius>0.45</radius>
              <length>0.3</length>
            </cylinder>
          </geometry>
          <max_contacts>1</max_contacts>
          <surface>
            <friction>
              <ode>
                <mu>1</mu>
                <mu2>1</mu2>
                <fdir1>0 0 1</fdir1>
                <slip1>0</slip1>
                <slip2>0</slip2>
              </ode>
              <torsional>
                <ode/>
              </torsional>
            </friction>
            <contact>
              <ode>
                <min_depth>0.005</min_depth>
                <kp>1e+08</kp>
              </ode>
            </contact>
            <bounce/>
          </surface>
        </collision>
        <self_collide>0</self_collide>
        <kinematic>0</kinematic>
      </link>
      <joint name='front_left_wheel_hinge' type='revolute'>
        <pose frame=''>0 0 0 0 -0 0</pose>
        <child>front_left_wheel</child>
        <parent>front_left_steering_wheel_block</parent>
        <axis>
          <xyz>1 0 0</xyz>
          <use_parent_model_frame>1</use_parent_model_frame>
          <limit>
            <lower>-1e+16</lower>
            <upper>1e+16</upper>
          </limit>
          <dynamics>
            <spring_reference>0</spring_reference>
            <spring_stiffness>0</spring_stiffness>
          </dynamics>
        </axis>
      </joint>
      <joint name='front_right_wheel_hinge' type='revolute'>
        <pose frame=''>0 0 0 0 -0 0</pose>
        <child>front_right_wheel</child>
        <parent>front_right_steering_wheel_block</parent>
        <axis>
          <xyz>1 0 0</xyz>
          <use_parent_model_frame>1</use_parent_model_frame>
          <limit>
            <lower>-1e+16</lower>
            <upper>1e+16</upper>
          </limit>
          <dynamics>
            <spring_reference>0</spring_reference>
            <spring_stiffness>0</spring_stiffness>
          </dynamics>
        </axis>
      </joint>
      <joint name='front_left_steering_wheel' type='revolute'>
        <pose frame=''>0 0 0 0 -0 0</pose>
        <child>front_left_steering_wheel_block</child>
        <parent>car</parent>
        <axis>
          <xyz>0 0 1</xyz>
          <dynamics>
            <damping>500</damping>
            <spring_reference>0</spring_reference>
            <spring_stiffness>0</spring_stiffness>
          </dynamics>
          <limit>
            <lower>-0.52359</lower>
            <upper>0.52359</upper>
          </limit>
          <use_parent_model_frame>1</use_parent_model_frame>
        </axis>
        <physics>
          <ode>
            <cfm_damping>1</cfm_damping>
            <limit>
              <cfm>0</cfm>
              <erp>0.9</erp>
            </limit>
          </ode>
        </physics>
      </joint>
      <joint name='front_right_steering_wheel' type='revolute'>
        <pose frame=''>0 0 0 0 -0 0</pose>
        <child>front_right_steering_wheel_block</child>
        <parent>car</parent>
        <axis>
          <xyz>0 0 1</xyz>
          <dynamics>
            <damping>500</damping>
            <spring_reference>0</spring_reference>
            <spring_stiffness>0</spring_stiffness>
          </dynamics>
          <limit>
            <lower>-0.52359</lower>
            <upper>0.52359</upper>
          </limit>
          <use_parent_model_frame>1</use_parent_model_frame>
        </axis>
        <physics>
          <ode>
            <cfm_damping>1</cfm_damping>
            <limit>
              <cfm>0</cfm>
              <erp>0.9</erp>
            </limit>
          </ode>
        </physics>
      </joint>
      <joint name='rear_right_wheel_hinge' type='revolute'>
        <pose frame=''>0 0 0 0 -0 0</pose>
        <child>rear_right_wheel</child>
        <parent>car</parent>
        <axis>
          <xyz>1 0 0</xyz>
          <use_parent_model_frame>1</use_parent_model_frame>
          <limit>
            <lower>-1e+16</lower>
            <upper>1e+16</upper>
          </limit>
          <dynamics>
            <spring_reference>0</spring_reference>
            <spring_stiffness>0</spring_stiffness>
          </dynamics>
        </axis>
      </joint>
      <joint name='rear_left_wheel_hinge' type='revolute'>
        <pose frame=''>0 0 0 0 -0 0</pose>
        <child>rear_left_wheel</child>
        <parent>car</parent>
        <axis>
          <xyz>1 0 0</xyz>
          <use_parent_model_frame>1</use_parent_model_frame>
          <limit>
            <lower>-1e+16</lower>
            <upper>1e+16</upper>
          </limit>
          <dynamics>
            <spring_reference>0</spring_reference>
            <spring_stiffness>0</spring_stiffness>
          </dynamics>
        </axis>
      </joint>
      <plugin name='carMotors' filename='libcarMotors.so'>
        <front_right_joint>front_right_wheel_hinge</front_right_joint>
        <front_left_joint>front_left_wheel_hinge</front_left_joint>
        <front_right_steering_joint>front_right_steering_wheel</front_right_steering_joint>
        <front_left_steering_joint>front_left_steering_wheel</front_left_steering_joint>
      </plugin>
    </model>
  </world>
</sdf>
